Workbook

Sheet Leverage finale
B2: Fiscal Year end January 31 | V2: COMMENTS
B3: In million | C3: Year | D3: 2018 | E3: 2019 | F3: 2020 | G3: 2021 | H3: 2022 | I3: 2023 | J3: 2024 | K3: 2025 | L3: 2026 | M3: 2027 | N3: 2028 | O3: 2029 | P3: 2030 | Q3: 2031 | R3: 2032 | S3: 2033 | T3: 2034 | U3: 2035 | AC3: Coverage ratio | AE3: Rating | AF3: Spread | AG3: Default probability | AJ3: Year 2025 | AK3: Iteration 0 | AL3: Iteration 1 | AM3: Iteration 2 | AN3: Iteration 3 | AO3: Iteration 4 | AP3: Iteration 5 | AQ3: Iteration 6 | AR3: Iteration 7 | AS3: Iteration 8 | AT3: Iteration 9 | AU3: Iteration 10
B4: Value of unlevered firm | AC4: > | AD4: ≤ to | AJ4: Trailing interest coverage ratio | AL4: =MAX(MIN($J$13/AK8,100000),-100000) -> 2.8643704 | AM4: =MAX(MIN($J$13/AL8,100000),-100000) -> 1.7744273 | AN4: =MAX(MIN($J$13/AM8,100000),-100000) -> 1.2181805 | AO4: =MAX(MIN($J$13/AN8,100000),-100000) -> 0.90935939 | AP4: =MAX(MIN($J$13/AO8,100000),-100000) -> 0.90935939 | AQ4: =MAX(MIN($J$13/AP8,100000),-100000) -> 0.90935939 | AR4: =MAX(MIN($J$13/AQ8,100000),-100000) -> 0.90935939 | AS4: =MAX(MIN($J$13/AR8,100000),-100000) -> 0.90935939 | ... AU4: =MAX(MIN($J$13/AT8,100000),-100000) -> 0.90935939
B5: Revenue growth | D5: 0 | E5: =+(E6-D6)/D6 -> 0.2601518 | F5: =+(F6-E6)/E6 -> 0.28730613 | G5: =+(G6-F6)/F6 -> 0.24295239 | H5: =+(H6-G6)/G6 -> 0.24656503 | I5: =+(I6-H6)/H6 -> 0.18345161 | J5: =+(J6-I6)/I6 -> 0.1117951 | K5: =+(K6-J6)/J6 -> 0.087156095 | L5: 0.12 | M5: 0.11 | N5: 0.097363199 | O5: 0.098704465 | P5: 0.092072049 | Q5: 0.08 | R5: 0.06 | S5: 0.06 | T5: 0.05 | U5: 0.04 | V5: We combined market and industry analysis with expectations derived from S&P Capital IQ via the CEDIF database. | AC5: -100000 | AD5: 0.199999 | AE5: D | AF5: 0.12 | AG5: 0.9 | AJ5: Credit rating | AL5: =VLOOKUP(AL4,$AC$5:$AG$17,3) -> BBB | AM5: =VLOOKUP(AM4,$AC$5:$AG$17,3) -> B+ | AN5: =VLOOKUP(AN4,$AC$5:$AG$17,3) -> CCC | AO5: =VLOOKUP(AO4,$AC$5:$AG$17,3) -> CCC | AP5: =VLOOKUP(AP4,$AC$5:$AG$17,3) -> CCC | AQ5: =VLOOKUP(AQ4,$AC$5:$AG$17,3) -> CCC | AR5: =VLOOKUP(AR4,$AC$5:$AG$17,3) -> CCC | AS5: =VLOOKUP(AS4,$AC$5:$AG$17,3) -> CCC | ... AU5: =VLOOKUP(AU4,$AC$5:$AG$17,3) -> CCC
B6: Revenue | D6: 10540 | E6: 13282 | F6: 17098 | G6: 21252 | H6: 26492 | I6: 31352 | J6: 34857 | K6: 37895 | L6: =+K6*(1+L5) -> 42442.4 | M6: =+L6*(1+M5) -> 47111.064 | N6: =+M6*(1+N5) -> 51697.948 | O6: =+N6*(1+O5) -> 56800.766 | P6: =+O6*(1+P5) -> 62030.529 | Q6: =+P6*(1+Q5) -> 66992.971 | R6: =+Q6*(1+R5) -> 71012.55 | S6: =+R6*(1+S5) -> 75273.303 | ... U6: =+T6*(1+U5) -> 82198.446 | AC6: 0.2 | AD6: 0.649999 | AE6: C | AF6: 0.105 | AG6: 0.3 | AJ6: Credit spread | AL6: =VLOOKUP(AL4,$AC$4:$AG$17,4) -> 0.025 | AM6: =VLOOKUP(AM4,$AC$4:$AG$17,4) -> 0.055 | AN6: =VLOOKUP(AN4,$AC$4:$AG$17,4) -> 0.0875 | AO6: =VLOOKUP(AO4,$AC$4:$AG$17,4) -> 0.0875 | AP6: =VLOOKUP(AP4,$AC$4:$AG$17,4) -> 0.0875 | AQ6: =VLOOKUP(AQ4,$AC$4:$AG$17,4) -> 0.0875 | AR6: =VLOOKUP(AR4,$AC$4:$AG$17,4) -> 0.0875 | AS6: =VLOOKUP(AS4,$AC$4:$AG$17,4) -> 0.0875 | ... AU6: =VLOOKUP(AU4,$AC$4:$AG$17,4) -> 0.0875
B7: Cost of Goods Sold | D7: 2773 | E7: 3451 | F7: 4235 | G7: 5438 | H7: 7026 | I7: 8360 | J7: 8541 | K7: 8643 | L7: =L6-L9*L6 -> 8284.7565 | M7: =M6-M9*M6 -> 9078.302 | N7: =N6-N9*N6 -> 9972.5341 | O7: =O6-O9*O6 -> 11604.397 | P7: =P6-P9*P6 -> 12064.938 | Q7: =Q6-Q9*Q6 -> 13030.133 | R7: =R6-R9*R6 -> 13811.941 | S7: =S6-S9*S6 -> 14640.657 | ... U7: =U6-U9*U6 -> 15987.598 | AC7: 0.65 | AD7: 0.799999 | AE7: CC | AF7: 0.095 | AG7: 0.2 | AJ7: Yield on debt | AL7: =AL6+$C$64 -> 0.0657 | AM7: =AM6+$C$64 -> 0.0957 | AN7: =AN6+$C$64 -> 0.1282 | AO7: =AO6+$C$64 -> 0.1282 | AP7: =AP6+$C$64 -> 0.1282 | AQ7: =AQ6+$C$64 -> 0.1282 | AR7: =AR6+$C$64 -> 0.1282 | AS7: =AS6+$C$64 -> 0.1282 | ... AU7: =AU6+$C$64 -> 0.1282
B8: % of revenues | D8: =+D7/D6 -> 0.26309298 | E8: =+E7/E6 -> 0.25982533 | F8: =+F7/F6 -> 0.24768979 | G8: =+G7/G6 -> 0.2558818 | H8: =+H7/H6 -> 0.26521214 | I8: =+I7/I6 -> 0.26664966 | J8: =+J7/J6 -> 0.24502969 | K8: =+K7/K6 -> 0.22807758 | ... U8: =+U7/U6 -> 0.1945 | AC8: 0.8 | AD8: 1.249999 | AE8: CCC | AF8: 0.0875 | AG8: 0.099 | AJ8: Interest paid | AK8: =$C$64*$C$55 -> 1749.4246 | AL8: =$C$55*AL7 -> 2824.0098 | AM8: =$C$55*AM7 -> 4113.5119 | AN8: =$C$55*AN7 -> 5510.4726 | AO8: =$C$55*AO7 -> 5510.4726 | AP8: =$C$55*AP7 -> 5510.4726 | AQ8: =$C$55*AQ7 -> 5510.4726 | AR8: =$C$55*AR7 -> 5510.4726 | AS8: =$C$55*AS7 -> 5510.4726 | ... AU8: =$C$55*AU7 -> 5510.4726
B9: Gross Profit Margin % | D9: =+D10/D6 -> 0.73690702 | E9: =+E10/E6 -> 0.74017467 | F9: =+F10/F6 -> 0.75231021 | G9: =+G10/G6 -> 0.7441182 | H9: =+H10/H6 -> 0.73478786 | I9: =+I10/I6 -> 0.73335034 | J9: =+J10/J6 -> 0.75497031 | K9: 0.8054 | L9: 0.8048 | M9: 0.8073 | N9: 0.8071 | O9: 0.7957 | P9: 0.8055 | Q9: 0.8055 | R9: 0.8055 | S9: 0.8055 | T9: 0.8055 | U9: 0.8055 | V9: data from Capital IQ | AC9: 1.25 | AD9: 1.499999 | AE9: B- | AF9: 0.0675 | AG9: 0.07 | AJ9: Prob of default | AL9: =VLOOKUP(AL4,$AC$5:$AG$17,5) -> 0.004 | AM9: =VLOOKUP(AM4,$AC$5:$AG$17,5) -> 0.03 | AN9: =VLOOKUP(AN4,$AC$5:$AG$17,5) -> 0.099 | AO9: =VLOOKUP(AO4,$AC$5:$AG$17,5) -> 0.099 | AP9: =VLOOKUP(AP4,$AC$5:$AG$17,5) -> 0.099 | AQ9: =VLOOKUP(AQ4,$AC$5:$AG$17,5) -> 0.099 | AR9: =VLOOKUP(AR4,$AC$5:$AG$17,5) -> 0.099 | AS9: =VLOOKUP(AS4,$AC$5:$AG$17,5) -> 0.099 | ... AU9: =VLOOKUP(AU4,$AC$5:$AG$17,5) -> 0.099
B10: Gross Profit | D10: =+D6-D7 -> 7767 | E10: =+E6-E7 -> 9831 | F10: =+F6-F7 -> 12863 | G10: =+G6-G7 -> 15814 | H10: =+H6-H7 -> 19466 | I10: =+I6-I7 -> 22992 | J10: =+J6-J7 -> 26316 | K10: =+K6-K7 -> 29252 | ... U10: =+U6-U7 -> 66210.849 | AC10: 1.5 | AD10: 1.749999 | AE10: B | AF10: 0.06 | AG10: 0.052 | AJ10: Cost of debt | AL10: =(1-AL9+AL9*$C$68)*(1+AL7)-1 -> 0.063184948 | AM10: =(1-AM9+AM9*$C$68)*(1+AM7)-1 -> 0.07630611 | AN10: =(1-AN9+AN9*$C$68)*(1+AN7)-1 -> 0.062301838 | AO10: =(1-AO9+AO9*$C$68)*(1+AO7)-1 -> 0.062301838 | AP10: =(1-AP9+AP9*$C$68)*(1+AP7)-1 -> 0.062301838 | AQ10: =(1-AQ9+AQ9*$C$68)*(1+AQ7)-1 -> 0.062301838 | AR10: =(1-AR9+AR9*$C$68)*(1+AR7)-1 -> 0.062301838 | AS10: =(1-AS9+AS9*$C$68)*(1+AS7)-1 -> 0.062301838 | ... AU10: =(1-AU9+AU9*$C$68)*(1+AU7)-1 -> 0.062301838
B11: Total operating expenses | D11: 7313 | E11: 9296 | F11: 12566 | G11: 15359 | H11: 18918 | I11: 21962 | J11: 21305 | K11: 22047 | L11: =+L6*L12 -> 26788.241 | M11: =+M6*M12 -> 28646.201 | N11: =+N6*N12 -> 31380.922 | O11: =+O6*O12 -> 34955.739 | P11: =+P6*P12 -> 37848.373 | Q11: =+Q6*Q12 -> 40923.148 | R11: =+R6*R12 -> 43469.72 | S11: =+S6*S12 -> 45995.9 | ... U11: =+U6*U12 -> 50265.544 | AC11: 1.75 | AD11: 1.999999 | AE11: B+ | AF11: 0.055 | AG11: 0.03
B12: Total operating expenses as % of revenues | D12: =+D11/D6 -> 0.69383302 | E12: =+E11/E6 -> 0.69989459 | F12: =+F11/F6 -> 0.73493976 | G12: =+G11/G6 -> 0.72270845 | H12: =+H11/H6 -> 0.71410237 | I12: =+I11/I6 -> 0.70049758 | J12: =+J11/J6 -> 0.61121152 | K12: =+K11/K6 -> 0.58179179 | L12: =+AVERAGE(I12:K12) -> 0.63116696 | M12: =+AVERAGE(J12:L12) -> 0.60805676 | N12: =+AVERAGE(K12:M12) -> 0.60700517 | O12: =+AVERAGE(L12:N12) -> 0.61540963 | P12: =+AVERAGE(M12:O12) -> 0.61015719 | Q12: =+AVERAGE(N12:P12) -> 0.61085733 | R12: =+AVERAGE(O12:Q12) -> 0.61214138 | S12: =+AVERAGE(P12:R12) -> 0.61105197 | ... U12: =+AVERAGE(R12:T12) -> 0.61151453 | AC12: 2.5 | AD12: 2.999999 | AE12: BBB | AF12: 0.025 | AG12: 0.004
B13: Taxable Income (EBIT) | D13: =+D10-D11 -> 454 | E13: =+E10-E11 -> 535 | F13: =+F10-F11 -> 297 | G13: =+G10-G11 -> 455 | H13: =+H10-H11 -> 548 | I13: =+I10-I11 -> 1030 | J13: =+J10-J11 -> 5011 | K13: =+K10-K11 -> 7205 | ... U13: =+U10-U11 -> 15945.305 | AC13: 3 | AD13: 4.249999 | AE13: A- | AF13: 0.0165 | AG13: 0.003 | AJ13: Year 2026 | AK13: Iteration 0 | AL13: Iteration 1 | AM13: Iteration 2 | AN13: Iteration 3 | AO13: Iteration 4 | AP13: Iteration 5 | AQ13: Iteration 6 | AR13: Iteration 7 | AS13: Iteration 8 | AT13: Iteration 9 | AU13: Iteration 10
B14: EBIT as % of revenues | D14: =+D13/D6 -> 0.043074004 | E14: =+E13/E6 -> 0.040280078 | F14: =+F13/F6 -> 0.017370453 | G14: =+G13/G6 -> 0.02140975 | H14: =+H13/H6 -> 0.02068549 | I14: =+I13/I6 -> 0.032852769 | J14: =+J13/J6 -> 0.14375879 | K14: =+K13/K6 -> 0.19013062 | ... U14: =+U13/U6 -> 0.19398547 | AC14: 4.25 | AD14: 5.499999 | AE14: A | AF14: 0.014 | AG14: 0.002 | AJ14: Trailing interest coverage ratio | AL14: =MAX(MIN($K$13/AK18,100000),-100000) -> 3.7900932 | AM14: =MAX(MIN($K$13/AL18,100000),-100000) -> 2.6967971 | AN14: =MAX(MIN($K$13/AM18,100000),-100000) -> 2.3478964 | AO14: =MAX(MIN($K$13/AN18,100000),-100000) -> 1.6118787 | AP14: =MAX(MIN($K$13/AO18,100000),-100000) -> 1.531845 | AQ14: =MAX(MIN($K$13/AP18,100000),-100000) -> 1.531845 | AR14: =MAX(MIN($K$13/AQ18,100000),-100000) -> 1.531845 | AS14: =MAX(MIN($K$13/AR18,100000),-100000) -> 1.531845 | ... AU14: =MAX(MIN($K$13/AT18,100000),-100000) -> 1.531845
B15: EBT | D15: 420 | E15: 983 | F15: 706 | G15: 2561 | H15: 1532 | I15: 660 | J15: 4950 | K15: 7438 | L15: =+L16*L6 -> 9144.5422 | M15: =+M16*M6 -> 10940.366 | N15: =+N16*N6 -> 13329.427 | O15: =+O16*O6 -> 14275.853 | P15: =+P16*P6 -> 16154.791 | Q15: =+Q16*Q6 -> 17869.743 | R15: =+R16*R6 -> 19304.548 | S15: =+S16*S6 -> 20788.183 | ... U15: =+U16*U6 -> 24741.726 | V15: data from Capital IQ (GAAP) | AC15: 5.5 | AD15: 6.499999 | AE15: A+ | AF15: 0.013 | AG15: 0.0015 | AJ15: Credit rating | AL15: =VLOOKUP(AL14,$AC$5:$AG$17,3) -> A- | AM15: =VLOOKUP(AM14,$AC$5:$AG$17,3) -> BBB | AN15: =VLOOKUP(AN14,$AC$5:$AG$17,3) -> B+ | AO15: =VLOOKUP(AO14,$AC$5:$AG$17,3) -> B | AP15: =VLOOKUP(AP14,$AC$5:$AG$17,3) -> B | AQ15: =VLOOKUP(AQ14,$AC$5:$AG$17,3) -> B | AR15: =VLOOKUP(AR14,$AC$5:$AG$17,3) -> B | AS15: =VLOOKUP(AS14,$AC$5:$AG$17,3) -> B | ... AU15: =VLOOKUP(AU14,$AC$5:$AG$17,3) -> B
B16: EBT % of revenues | D16: =+D15/D6 -> 0.039848197 | E16: =+E15/E6 -> 0.074009938 | F16: =+F15/F6 -> 0.041291379 | G16: =+G15/G6 -> 0.12050631 | H16: =+H15/H6 -> 0.057828778 | I16: =+I15/I6 -> 0.021051289 | J16: =+J15/J6 -> 0.14200878 | K16: =+K15/K6 -> 0.19627919 | L16: 0.21545771 | M16: 0.23222498 | N16: 0.25783281 | O16: 0.25133205 | P16: 0.2604329 | Q16: 0.26674056 | R16: 0.271847 | S16: 0.27616941 | T16: 0.27962481 | U16: 0.30099992 | AC16: 6.5 | AD16: 8.499999 | AE16: AA | AF16: 0.0115 | AG16: 0.0005 | AJ16: Credit spread | AL16: =VLOOKUP(AL14,$AC$5:$AG$17,4) -> 0.0165 | AM16: =VLOOKUP(AM14,$AC$5:$AG$17,4) -> 0.025 | AN16: =VLOOKUP(AN14,$AC$5:$AG$17,4) -> 0.055 | AO16: =VLOOKUP(AO14,$AC$5:$AG$17,4) -> 0.06 | AP16: =VLOOKUP(AP14,$AC$5:$AG$17,4) -> 0.06 | AQ16: =VLOOKUP(AQ14,$AC$5:$AG$17,4) -> 0.06 | AR16: =VLOOKUP(AR14,$AC$5:$AG$17,4) -> 0.06 | AS16: =VLOOKUP(AS14,$AC$5:$AG$17,4) -> 0.06 | ... AU16: =VLOOKUP(AU14,$AC$5:$AG$17,4) -> 0.06
B17: Taxes | D17: -60 | E17: 127 | F17: -580 | G17: 1511 | H17: -88 | I17: -452 | J17: -814 | K17: -1241 | L17: =+L15*L19 -> -1507.4398 | M17: =+M15*M19 -> -1803.4739 | N17: =+N15*N19 -> -2197.3007 | O17: =+O15*O19 -> -2353.3151 | P17: =+P15*P19 -> -2663.0501 | Q17: =+Q15*Q19 -> -2945.7529 | R17: =+R15*R19 -> -3182.2746 | S17: =+S15*S19 -> -3426.8456 | ... U17: =+U15*U19 -> -4078.5706 | AC17: 8.5 | AD17: 100000 | AE17: AAA | AF17: 0.0065 | AG17: 0.0001 | AJ17: Yield on debt | AL17: =AL16+$C$64 -> 0.0572 | AM17: =AM16+$C$64 -> 0.0657 | AN17: =AN16+$C$64 -> 0.0957 | AO17: =AO16+$C$64 -> 0.1007 | AP17: =AP16+$C$64 -> 0.1007 | AQ17: =AQ16+$C$64 -> 0.1007 | AR17: =AR16+$C$64 -> 0.1007 | AS17: =AS16+$C$64 -> 0.1007 | ... AU17: =AU16+$C$64 -> 0.1007
B18: Net income | D18: =+D15+D17 -> 360 | E18: =+E15+E17 -> 1110 | F18: =+F15+F17 -> 126 | G18: =+G15+G17 -> 4072 | H18: =+H15+H17 -> 1444 | I18: =+I15+I17 -> 208 | J18: =+J15+J17 -> 4136 | K18: =+K15+K17 -> 6197 | ... U18: =+U15+U17 -> 20663.155 | V18: data from Capital IQ (GAAP) | AJ18: Interest paid | AK18: =+$D$55*$C$64 -> 1901.0087 | AL18: =$D$55*AL17 -> 2671.6879 | AM18: =$D$55*AM17 -> 3068.7044 | AN18: =$D$55*AN17 -> 4469.9393 | AO18: =$D$55*AO17 -> 4703.4785 | AP18: =$D$55*AP17 -> 4703.4785 | AQ18: =$D$55*AQ17 -> 4703.4785 | AR18: =$D$55*AR17 -> 4703.4785 | AS18: =$D$55*AS17 -> 4703.4785 | ... AU18: =$D$55*AU17 -> 4703.4785
B19: Effective Tax Rate | D19: =+D17/D15 -> -0.14285714 | E19: =+E17/E15 -> 0.12919634 | F19: =+F17/F15 -> -0.82152975 | G19: =+G17/G15 -> 0.5900039 | H19: =+H17/H15 -> -0.057441253 | I19: =+I17/I15 -> -0.68484848 | J19: =+J17/J15 -> -0.16444444 | K19: =+K17/K15 -> -0.16684593 | L19: =+AVERAGE($D$19:$K$19) -> -0.16484584 | M19: =+AVERAGE($D$19:$K$19) -> -0.16484584 | N19: =+AVERAGE($D$19:$K$19) -> -0.16484584 | O19: =+AVERAGE($D$19:$K$19) -> -0.16484584 | P19: =+AVERAGE($D$19:$K$19) -> -0.16484584 | Q19: =+AVERAGE($D$19:$K$19) -> -0.16484584 | R19: =+AVERAGE($D$19:$K$19) -> -0.16484584 | S19: =+AVERAGE($D$19:$K$19) -> -0.16484584 | ... U19: =+AVERAGE($D$19:$K$19) -> -0.16484584 | V19: We assumed that the effective tax rate for 2026–2035 corresponds to the average ETR observed in the previous years. | AJ19: Prob of default | AL19: =VLOOKUP(AL14,$AC$5:$AG$17,5) -> 0.003 | AM19: =VLOOKUP(AM14,$AC$5:$AG$17,5) -> 0.004 | AN19: =VLOOKUP(AN14,$AC$5:$AG$17,5) -> 0.03 | AO19: =VLOOKUP(AO14,$AC$5:$AG$17,5) -> 0.052 | AP19: =VLOOKUP(AP14,$AC$5:$AG$17,5) -> 0.052 | AQ19: =VLOOKUP(AQ14,$AC$5:$AG$17,5) -> 0.052 | AR19: =VLOOKUP(AR14,$AC$5:$AG$17,5) -> 0.052 | AS19: =VLOOKUP(AS14,$AC$5:$AG$17,5) -> 0.052 | ... AU19: =VLOOKUP(AU14,$AC$5:$AG$17,5) -> 0.052
B20: Cash flow from operations | D20: 2738 | E20: 3398 | F20: 4331 | G20: 4801 | H20: 6000 | I20: 7111 | J20: 10234 | K20: 13092 | L20: =+L21*L6 -> 11073.199 | M20: =+M21*M6 -> 12291.25 | N20: =+N21*N6 -> 13487.966 | O20: =+O21*O6 -> 14819.288 | P20: =+P21*P6 -> 16183.73 | Q20: =+Q21*Q6 -> 17478.429 | R20: =+R21*R6 -> 18527.135 | S20: =+S21*S6 -> 19638.763 | ... U20: =+U21*U6 -> 21445.529 | AJ20: Cost of debt | AL20: =(1-AL19+AL19*$C$68)*(1+AL17)-1 -> 0.055328756 | AM20: =(1-AM19+AM19*$C$68)*(1+AM17)-1 -> 0.063184948 | AN20: =(1-AN19+AN19*$C$68)*(1+AN17)-1 -> 0.07630611 | AO20: =(1-AO19+AO19*$C$68)*(1+AO17)-1 -> 0.066930524 | AP20: =(1-AP19+AP19*$C$68)*(1+AP17)-1 -> 0.066930524 | AQ20: =(1-AQ19+AQ19*$C$68)*(1+AQ17)-1 -> 0.066930524 | AR20: =(1-AR19+AR19*$C$68)*(1+AR17)-1 -> 0.066930524 | AS20: =(1-AS19+AS19*$C$68)*(1+AS17)-1 -> 0.066930524 | ... AU20: =(1-AU19+AU19*$C$68)*(1+AU17)-1 -> 0.066930524
B21: Cash flow from Operations as % of revenues | D21: =+D20/D6 -> 0.2597723 | E21: =+E20/E6 -> 0.25583496 | F21: =+F20/F6 -> 0.25330448 | G21: =+G20/G6 -> 0.22590815 | H21: =+H20/H6 -> 0.22648347 | I21: =+I20/I6 -> 0.22681169 | J21: =+J20/J6 -> 0.29359956 | K21: =+K20/K6 -> 0.34548093 | L21: =+AVERAGE($D$21:$K$21) -> 0.26089944 | M21: =+L21 -> 0.26089944 | N21: =+M21 -> 0.26089944 | O21: =+N21 -> 0.26089944 | P21: =+O21 -> 0.26089944 | Q21: =+P21 -> 0.26089944 | R21: =+Q21 -> 0.26089944 | S21: =+R21 -> 0.26089944 | T21: =+S21 -> 0.26089944 | U21: =+T21 -> 0.26089944 | V21: We used the average percentage of CFFO/revenues for projections
B22: Increase in gross PPE | D22: 417 | E22: 431 | F22: 342 | G22: 238 | H22: 802 | I22: 1188 | J22: 437 | K22: 77 | L22: =(1+AVERAGE($E$23:$K$23))*K22 -> 87.098816 | M22: =(1+AVERAGE($E$23:$K$23))*L22 -> 98.522127 | N22: =(1+AVERAGE($E$23:$K$23))*M22 -> 111.44364 | O22: =(1+AVERAGE($E$23:$K$23))*N22 -> 126.05986 | P22: =(1+AVERAGE($E$23:$K$23))*O22 -> 142.59305 | Q22: =(1+AVERAGE($E$23:$K$23))*P22 -> 161.29462 | R22: =(1+AVERAGE($E$23:$K$23))*Q22 -> 182.44897 | S22: =(1+AVERAGE($E$23:$K$23))*R22 -> 206.37778 | ... U22: =(1+AVERAGE($E$23:$K$23))*T22 -> 264.06205 | V22: We calculated the average percentage increase and then applied it as PPE(t-1) × (1 + average increase
B23: % increase | E23: =+(E22-D22)/D22 -> 0.033573141 | F23: =+(F22-E22)/E22 -> -0.20649652 | G23: =+(G22-F22)/F22 -> -0.30409357 | H23: =+(H22-G22)/G22 -> 2.3697479 | I23: =+(I22-H22)/H22 -> 0.48129676 | J23: =+(J22-I22)/I22 -> -0.63215488 | K23: =+(K22-J22)/J22 -> -0.82379863 | L23: =+(L22-K22)/K22 -> 0.13115346 | ... U23: =+(U22-T22)/T22 -> 0.13115346 | AJ23: Year 2027 | AK23: Iteration 0 | AL23: Iteration 1 | AM23: Iteration 2 | AN23: Iteration 3 | AO23: Iteration 4 | AP23: Iteration 5 | AQ23: Iteration 6 | AR23: Iteration 7 | AS23: Iteration 8 | AT23: Iteration 9 | AU23: Iteration 10
B24: Free Cash Flow | D24: =+D20-D22 -> 2321 | E24: =+E20-E22 -> 2967 | F24: =+F20-F22 -> 3989 | G24: =+G20-G22 -> 4563 | H24: =+H20-H22 -> 5198 | I24: =+I20-I22 -> 5923 | J24: =+J20-J22 -> 9797 | K24: =+K20-K22 -> 13015 | ... U24: =+U20-U22 -> 21181.467 | AJ24: Trailing interest coverage ratio | AL24: =MAX(MIN($L$13/AK28,100000),-100000) -> 3.5713553 | AM24: =MAX(MIN($L$13/AL28,100000),-100000) -> 2.5411566 | AN24: =MAX(MIN($L$13/AM28,100000),-100000) -> 2.2123921 | AO24: =MAX(MIN($L$13/AN28,100000),-100000) -> 1.5188522 | AP24: =MAX(MIN($L$13/AO28,100000),-100000) -> 1.4434375 | AQ24: =MAX(MIN($L$13/AP28,100000),-100000) -> 1.3433841 | AR24: =MAX(MIN($L$13/AQ28,100000),-100000) -> 1.3433841 | AS24: =MAX(MIN($L$13/AR28,100000),-100000) -> 1.3433841 | ... AU24: =MAX(MIN($L$13/AT28,100000),-100000) -> 1.3433841
B25: Terminal Value | U25: =+U24*(1+C69)/(C63-C69) -> 375893.93 | AJ25: Credit rating | AL25: =VLOOKUP(AL24,$AC$5:$AG$17,3) -> A- | AM25: =VLOOKUP(AM24,$AC$5:$AG$17,3) -> BBB | AN25: =VLOOKUP(AN24,$AC$5:$AG$17,3) -> B+ | AO25: =VLOOKUP(AO24,$AC$5:$AG$17,3) -> B | AP25: =VLOOKUP(AP24,$AC$5:$AG$17,3) -> B- | AQ25: =VLOOKUP(AQ24,$AC$5:$AG$17,3) -> B- | AR25: =VLOOKUP(AR24,$AC$5:$AG$17,3) -> B- | AS25: =VLOOKUP(AS24,$AC$5:$AG$17,3) -> B- | ... AU25: =VLOOKUP(AU24,$AC$5:$AG$17,3) -> B-
B26: Total Free Cash Flow | D26: =+D24 -> 2321 | E26: =+E24 -> 2967 | F26: =+F24 -> 3989 | G26: =+G24 -> 4563 | H26: =+H24 -> 5198 | I26: =+I24 -> 5923 | J26: =+J24 -> 9797 | K26: =+K24 -> 13015 | ... P26: =+P24 -> 16041.137 | Q26: =+Q24+Q25 -> 17317.134 | R26: =+R24+R25 -> 18344.686 | S26: =+S24+S25 -> 19432.385 | T26: =+T24+T25 -> 20387.256 | U26: =+U24+U25 -> 397075.39 | AJ26: Credit spread | AL26: =VLOOKUP(AL24,$AC$5:$AG$17,4) -> 0.0165 | AM26: =VLOOKUP(AM24,$AC$5:$AG$17,4) -> 0.025 | AN26: =VLOOKUP(AN24,$AC$5:$AG$17,4) -> 0.055 | AO26: =VLOOKUP(AO24,$AC$5:$AG$17,4) -> 0.06 | AP26: =VLOOKUP(AP24,$AC$5:$AG$17,4) -> 0.0675 | AQ26: =VLOOKUP(AQ24,$AC$5:$AG$17,4) -> 0.0675 | AR26: =VLOOKUP(AR24,$AC$5:$AG$17,4) -> 0.0675 | AS26: =VLOOKUP(AS24,$AC$5:$AG$17,4) -> 0.0675 | ... AU26: =VLOOKUP(AU24,$AC$5:$AG$17,4) -> 0.0675
B27: Value of unlevered firm (at February of every year) | K27: =+NPV($C$63,K26:U26) -> 244180.8 | L27: =+NPV($C$63,L26:U26) -> 253770.6 | M27: =+NPV($C$63,M26:U26) -> 266277.06 | N27: =+NPV($C$63,N26:U26) -> 278734.66 | O27: =+NPV($C$63,O26:U26) -> 291161.72 | P27: =+NPV($C$63,P26:U26) -> 303422.5 | Q27: =+NPV($C$63,Q26:U26) -> 315470.4 | R27: =+NPV($C$63,R26:U26) -> 327357.63 | S27: =+NPV($C$63,S26:U26) -> 339317.75 | T27: =+NPV($C$63,T26:U26) -> 351297.37 | U27: =+NPV($C$63,U26) -> 363431.12 | AJ27: Yield on debt | AL27: =AL26+$C$64 -> 0.0572 | AM27: =AM26+$C$64 -> 0.0657 | AN27: =AN26+$C$64 -> 0.0957 | AO27: =AO26+$C$64 -> 0.1007 | AP27: =AP26+$C$64 -> 0.1082 | AQ27: =AQ26+$C$64 -> 0.1082 | AR27: =AR26+$C$64 -> 0.1082 | AS27: =AS26+$C$64 -> 0.1082 | ... AU27: =AU26+$C$64 -> 0.1082
J28: EXCESS CASH | K28: ='Excess Cash'!I5 -> 3739.2 | L28: =K28*(1+$C$64) -> 3891.3854 | M28: =L28*(1+$C$64) -> 4049.7648 | N28: =M28*(1+$C$64) -> 4214.5903 | O28: =N28*(1+$C$64) -> 4386.1241 | P28: =O28*(1+$C$64) -> 4564.6393 | Q28: =P28*(1+$C$64) -> 4750.4202 | R28: =Q28*(1+$C$64) -> 4943.7623 | S28: =R28*(1+$C$64) -> 5144.9734 | ... U28: =T28*(1+$C$64) -> 5572.2968 | AJ28: Interest paid | AK28: =$C$64*$E$55 -> 2063.4751 | AL28: =$E$55*AL27 -> 2900.0191 | AM28: =$E$55*AM27 -> 3330.966 | AN28: =$E$55*AN27 -> 4851.955 | AO28: =$E$55*AO27 -> 5105.4532 | AP28: =$E$55*AP27 -> 5485.7005 | AQ28: =$E$55*AQ27 -> 5485.7005 | AR28: =$E$55*AR27 -> 5485.7005 | AS28: =$E$55*AS27 -> 5485.7005 | ... AU28: =$E$55*AU27 -> 5485.7005
I29: Adj. Value of Unlevered Firm | K29: =K28+K27 -> 247920 | L29: =L28+L27 -> 257661.98 | M29: =M28+M27 -> 270326.82 | N29: =N28+N27 -> 282949.25 | O29: =O28+O27 -> 295547.85 | P29: =P28+P27 -> 307987.14 | Q29: =Q28+Q27 -> 320220.82 | R29: =R28+R27 -> 332301.39 | ... U29: =U28+U27 -> 369003.41 | AJ29: Prob of default | AL29: =VLOOKUP(AL24,$AC$5:$AG$17,5) -> 0.003 | AM29: =VLOOKUP(AM24,$AC$5:$AG$17,5) -> 0.004 | AN29: =VLOOKUP(AN24,$AC$5:$AG$17,5) -> 0.03 | AO29: =VLOOKUP(AO24,$AC$5:$AG$17,5) -> 0.052 | AP29: =VLOOKUP(AP24,$AC$5:$AG$17,5) -> 0.07 | AQ29: =VLOOKUP(AQ24,$AC$5:$AG$17,5) -> 0.07 | AR29: =VLOOKUP(AR24,$AC$5:$AG$17,5) -> 0.07 | AS29: =VLOOKUP(AS24,$AC$5:$AG$17,5) -> 0.07 | ... AU29: =VLOOKUP(AU24,$AC$5:$AG$17,5) -> 0.07
AJ30: Cost of debt | AL30: =(1-AL29+AL29*$C$68)*(1+AL27)-1 -> 0.055328756 | AM30: =(1-AM29+AM29*$C$68)*(1+AM27)-1 -> 0.063184948 | AN30: =(1-AN29+AN29*$C$68)*(1+AN27)-1 -> 0.07630611 | AO30: =(1-AO29+AO29*$C$68)*(1+AO27)-1 -> 0.066930524 | AP30: =(1-AP29+AP29*$C$68)*(1+AP27)-1 -> 0.06243134 | AQ30: =(1-AQ29+AQ29*$C$68)*(1+AQ27)-1 -> 0.06243134 | AR30: =(1-AR29+AR29*$C$68)*(1+AR27)-1 -> 0.06243134 | AS30: =(1-AS29+AS29*$C$68)*(1+AS27)-1 -> 0.06243134 | ... AU30: =(1-AU29+AU29*$C$68)*(1+AU27)-1 -> 0.06243134
B32: Value of Interest Tax Shields | K32: 2025 | L32: 2026 | M32: 2027 | N32: 2028 | O32: 2029 | P32: 2030 | Q32: 2031 | R32: 2032 | S32: 2033 | T32: 2034 | U32: 2035
B33: Interest paid | K33: =+AU8 -> 5510.4726 | L33: =+AU18 -> 4703.4785 | M33: =+AU28 -> 5485.7005 | N33: =+AU38 -> 3633.3287 | O33: =+AU48 -> 3357.4592 | P33: =+AU58 -> 4023.1017 | Q33: =+BA8 -> 0 | R33: =+BA18 -> 0 | S33: =+BA28 -> 0 | T33: =+BA38 -> 0 | U33: =+AZ58 -> 0 | AJ33: Year 2028 | AK33: Iteration 0 | AL33: Iteration 1 | AM33: Iteration 2 | AN33: Iteration 3 | AO33: Iteration 4 | AP33: Iteration 5 | AQ33: Iteration 6 | AR33: Iteration 7 | AS33: Iteration 8 | AT33: Iteration 9 | AU33: Iteration 10
B34: PV Interest tax shields | K34: =$C$62*$K$33 -> 908.37851 | L34: =$C$62*$K$33 -> 908.37851 | M34: =$C$62*$K$33 -> 908.37851 | N34: =$C$62*$K$33 -> 908.37851 | O34: =$C$62*$K$33 -> 908.37851 | P34: =$C$62*$K$33 -> 908.37851 | Q34: =$C$62*$K$33 -> 908.37851 | R34: =$C$62*$K$33 -> 908.37851 | ... U34: =$C$62*$K$33 -> 908.37851 | AJ34: Trailing interest coverage ratio | AL34: =MAX(MIN($M$13/AK38,100000),-100000) -> 4.1703527 | AM34: =MAX(MIN($M$13/AL38,100000),-100000) -> 2.9673663 | AN34: =MAX(MIN($M$13/AM38,100000),-100000) -> 2.5834605 | AO34: =MAX(MIN($M$13/AN38,100000),-100000) -> 2.5834605 | AP34: =MAX(MIN($M$13/AO38,100000),-100000) -> 2.5834605 | AQ34: =MAX(MIN($M$13/AP38,100000),-100000) -> 2.5834605 | AR34: =MAX(MIN($M$13/AQ38,100000),-100000) -> 2.5834605 | AS34: =MAX(MIN($M$13/AR38,100000),-100000) -> 2.5834605 | ... AU34: =MAX(MIN($M$13/AT38,100000),-100000) -> 2.5834605
U35: =C62*M55 -> 12421.155 | AJ35: Credit rating | AL35: =VLOOKUP(AL34,$AC$5:$AG$17,3) -> A- | AM35: =VLOOKUP(AM34,$AC$5:$AG$17,3) -> BBB | AN35: =VLOOKUP(AN34,$AC$5:$AG$17,3) -> BBB | AO35: =VLOOKUP(AO34,$AC$5:$AG$17,3) -> BBB | AP35: =VLOOKUP(AP34,$AC$5:$AG$17,3) -> BBB | AQ35: =VLOOKUP(AQ34,$AC$5:$AG$17,3) -> BBB | AR35: =VLOOKUP(AR34,$AC$5:$AG$17,3) -> BBB | AS35: =VLOOKUP(AS34,$AC$5:$AG$17,3) -> BBB | ... AU35: =VLOOKUP(AU34,$AC$5:$AG$17,3) -> BBB
B36: Total value of tax shields | K36: =K34+K35 -> 908.37851 | L36: =L34+L35 -> 908.37851 | M36: =M34+M35 -> 908.37851 | N36: =N34+N35 -> 908.37851 | O36: =O34+O35 -> 908.37851 | P36: =P34+P35 -> 908.37851 | Q36: =Q34+Q35 -> 908.37851 | R36: =R34+R35 -> 908.37851 | ... U36: =U34+U35 -> 13329.534 | AJ36: Credit spread | AL36: =VLOOKUP(AL34,$AC$4:$AG$17,4) -> 0.0165 | AM36: =VLOOKUP(AM34,$AC$4:$AG$17,4) -> 0.025 | AN36: =VLOOKUP(AN34,$AC$4:$AG$17,4) -> 0.025 | AO36: =VLOOKUP(AO34,$AC$4:$AG$17,4) -> 0.025 | AP36: =VLOOKUP(AP34,$AC$4:$AG$17,4) -> 0.025 | AQ36: =VLOOKUP(AQ34,$AC$4:$AG$17,4) -> 0.025 | AR36: =VLOOKUP(AR34,$AC$4:$AG$17,4) -> 0.025 | AS36: =VLOOKUP(AS34,$AC$4:$AG$17,4) -> 0.025 | ... AU36: =VLOOKUP(AU34,$AC$4:$AG$17,4) -> 0.025
B37: Cost of debt | K37: =+$AU$10 -> 0.062301838 | L37: =+$AU$20 -> 0.066930524 | M37: =+$AU$30 -> 0.06243134 | N37: =+$AU$30 -> 0.06243134 | O37: =+$AU$40 -> 0.063184948 | P37: =+$AU$50 -> 0.055328756 | Q37: =+$AU$10 -> 0.062301838 | R37: =+$AU$20 -> 0.066930524 | S37: =+$AU$30 -> 0.06243134 | T37: =+$AU$30 -> 0.06243134 | U37: =+$AU$50 -> 0.055328756 | AJ37: Yield on debt | AL37: =AL36+$C$64 -> 0.0572 | AM37: =AM36+$C$64 -> 0.0657 | AN37: =AN36+$C$64 -> 0.0657 | AO37: =AO36+$C$64 -> 0.0657 | AP37: =AP36+$C$64 -> 0.0657 | AQ37: =AQ36+$C$64 -> 0.0657 | AR37: =AR36+$C$64 -> 0.0657 | AS37: =AS36+$C$64 -> 0.0657 | ... AU37: =AU36+$C$64 -> 0.0657
B38: Tax Shield Discount Rate | K38: =IF(K3=2025,K37,(1+$C$63)*(((1+K37)/(1+$C$63))^(1/(K3-2024)))-1) -> 0.062301838 | L38: =IF(L3=2025,L37,(1+$C$63)*(((1+L37)/(1+$C$63))^(1/(L3-2024)))-1) -> 0.079676135 | M38: =IF(M3=2025,M37,(1+$C$63)*(((1+M37)/(1+$C$63))^(1/(M3-2024)))-1) -> 0.082432609 | N38: =IF(N3=2025,N37,(1+$C$63)*(((1+N37)/(1+$C$63))^(1/(N3-2024)))-1) -> 0.084959099 | O38: =IF(O3=2025,O37,(1+$C$63)*(((1+O37)/(1+$C$63))^(1/(O3-2024)))-1) -> 0.086631912 | P38: =IF(P3=2025,P37,(1+$C$63)*(((1+P37)/(1+$C$63))^(1/(P3-2024)))-1) -> 0.086276411 | Q38: =IF(Q3=2025,Q37,(1+$C$63)*(((1+Q37)/(1+$C$63))^(1/(Q3-2024)))-1) -> 0.08819716 | R38: =IF(R3=2025,R37,(1+$C$63)*(((1+R37)/(1+$C$63))^(1/(R3-2024)))-1) -> 0.089335165 | ... U38: =IF(U3=2025,U37,(1+$C$63)*(((1+U37)/(1+$C$63))^(1/(U3-2024)))-1) -> 0.089134442 | AJ38: Interest paid | AK38: =$C$64*$F$55 -> 2250.7835 | AL38: =$F$55*AL37 -> 3163.2633 | AM38: =$F$55*AM37 -> 3633.3287 | AN38: =$F$55*AN37 -> 3633.3287 | AO38: =$F$55*AO37 -> 3633.3287 | AP38: =$F$55*AP37 -> 3633.3287 | AQ38: =$F$55*AQ37 -> 3633.3287 | AR38: =$F$55*AR37 -> 3633.3287 | AS38: =$F$55*AS37 -> 3633.3287 | ... AU38: =$F$55*AU37 -> 3633.3287
B39: Present value of tax shields (beginning of year) | K39: =K36/(1+K38)^(K3-2024) -> 855.10396 | L39: =L36/(1+L38)^(L3-2024) -> 779.25545 | M39: =M36/(1+M38)^(M3-2024) -> 716.24936 | N39: =N36/(1+N38)^(N3-2024) -> 655.56142 | O39: =O36/(1+O38)^(O3-2024) -> 599.59027 | P39: =P36/(1+P38)^(P3-2024) -> 552.87221 | Q39: =Q36/(1+Q38)^(Q3-2024) -> 502.70561 | R39: =R36/(1+R38)^(R3-2024) -> 458.11516 | ... U39: =U36/(1+U38)^(U3-2024) -> 5210.9697 | AJ39: Prob of default | AL39: =VLOOKUP(AL34,$AC$5:$AG$17,5) -> 0.003 | AM39: =VLOOKUP(AM34,$AC$5:$AG$17,5) -> 0.004 | AN39: =VLOOKUP(AN34,$AC$5:$AG$17,5) -> 0.004 | AO39: =VLOOKUP(AO34,$AC$5:$AG$17,5) -> 0.004 | AP39: =VLOOKUP(AP34,$AC$5:$AG$17,5) -> 0.004 | AQ39: =VLOOKUP(AQ34,$AC$5:$AG$17,5) -> 0.004 | AR39: =VLOOKUP(AR34,$AC$5:$AG$17,5) -> 0.004 | AS39: =VLOOKUP(AS34,$AC$5:$AG$17,5) -> 0.004 | ... AU39: =VLOOKUP(AU34,$AC$5:$AG$17,5) -> 0.004
B40: Sum (PVTS) | K40: =SUM(K39:U39) -> 11136.895 | AJ40: Cost of debt | AL40: =(1-AL39+AL39*$C$68)*(1+AL37)-1 -> 0.055328756 | AM40: =(1-AM39+AM39*$C$68)*(1+AM37)-1 -> 0.063184948 | AN40: =(1-AN39+AN39*$C$68)*(1+AN37)-1 -> 0.063184948 | AO40: =(1-AO39+AO39*$C$68)*(1+AO37)-1 -> 0.063184948 | AP40: =(1-AP39+AP39*$C$68)*(1+AP37)-1 -> 0.063184948 | AQ40: =(1-AQ39+AQ39*$C$68)*(1+AQ37)-1 -> 0.063184948 | AR40: =(1-AR39+AR39*$C$68)*(1+AR37)-1 -> 0.063184948 | AS40: =(1-AS39+AS39*$C$68)*(1+AS37)-1 -> 0.063184948 | ... AU40: =(1-AU39+AU39*$C$68)*(1+AU37)-1 -> 0.063184948
B41: PVTS (every year) | K41: =K36/(1+K38)+L36/((1+L38)^2)+M36/((1+M38)^3)+N36/((1+N38)^4)+O36/((1+O38)^5)+P36/((1+P38)^6)+Q36/((1+Q38)^7)+R36/((1+R38)^8)+S36/((1+S38)^9)+T36/((1+T38)^10)+U36/((1+U38)^11) -> 11136.895 | L41: =L36/(1+L38)+M36/((1+M38)^2)+N36/((1+N38)^3)+O36/((1+O38)^4)+P36/((1+P38)^5)+Q36/((1+Q38)^6)+R36/((1+R38)^7)+S36/((1+S38)^8)+T36/((1+T38)^9)+U36/((1+U38)^10) -> 11180.054 | M41: =M36/(1+M38)+N36/((1+N38)^2)+O36/((1+O38)^3)+P36/((1+P38)^4)+Q36/((1+Q38)^5)+R36/((1+R38)^6)+S36/((1+S38)^7)+T36/((1+T38)^8)+U36/((1+U38)^9) -> 11248.506 | N41: =N36/(1+N38)+O36/((1+O38)^2)+P36/((1+P38)^3)+Q36/((1+Q38)^4)+R36/((1+R38)^5)+S36/((1+S38)^6)+T36/((1+T38)^7)+U36/((1+U38)^8) -> 11330.027 | O41: =O36/(1+O38)+P36/((1+P38)^2)+Q36/((1+Q38)^3)+R36/((1+R38)^4)+S36/((1+S38)^5)+T36/((1+T38)^6)+U36/((1+U38)^7) -> 11423.829 | P41: =P36/(1+P38)+Q36/((1+Q38)^2)+R36/((1+R38)^3)+S36/((1+S38)^4)+T36/((1+T38)^5)+U36/((1+U38)^6) -> 11529.122 | Q41: =Q36/((1+Q38)^1)+R36/((1+R38)^2)+S36/((1+S38)^3)+T36/((1+T38)^4)+U36/((1+U38)^5) -> 11645.678 | R41: =+R36/((1+R38)^1)+S36/((1+S38)^2)+T36/((1+T38)^3)+U36/((1+U38)^4) -> 11774.986 | S41: =+S36/((1+S38)^1)+T36/((1+T38)^2)+U36/((1+U38)^3) -> 11916.641 | T41: =+T36/((1+T38)^1)+U36/((1+U38)^2) -> 12070.782 | U41: =+U36/((1+U38)^1) -> 12238.649
B43: Costs of Financial distress | AJ43: Year 2029 | AK43: Iteration 0 | AL43: Iteration 1 | AM43: Iteration 2 | AN43: Iteration 3 | AO43: Iteration 4 | AP43: Iteration 5 | AQ43: Iteration 6 | AR43: Iteration 7 | AS43: Iteration 8 | AT43: Iteration 9 | AU43: Iteration 10
...

Sheet Bonds
C1: DEBT INCREASE/YEAR | D1: 2025 | E1: 2026 | F1: 2027 | G1: 2028 | H1: 2029 | I1: 2030 | J1: 2031 | K1: 2032 | L1: 2033 | M1: 2034 | N1: 2035
C2: Debt | D2: =+'Leverage finale'!C55 -> 42983.406 | E2: =+'Leverage finale'!D55 -> 46707.83 | F2: =+'Leverage finale'!E55 -> 50699.634 | G2: =+'Leverage finale'!F55 -> 55301.806 | H2: =+'Leverage finale'!G55 -> 58696.84 | I2: =+'Leverage finale'!H55 -> 61234.425 | J2: =+'Leverage finale'!I55 -> 64168.61 | K2: =+'Leverage finale'!J55 -> 66372.874 | ... N2: =+'Leverage finale'!M55 -> 75350.127
C3: Amount for bond issuance (in million) | D3: =+D2 -> 42983.406 | E3: =+E2-D2 -> 3724.4243 | F3: =+F2-E2 -> 3991.8045 | G3: =+G2-F2 -> 4602.1717 | H3: =+H2-G2 -> 3395.0333 | I3: =+I2-H2 -> 2537.5856 | J3: =+J2-I2 -> 2934.1851 | K3: =+K2-J2 -> 2204.2642 | L3: =+L2-K2 -> 2198.1695 | ... N3: =+N2-M2 -> 2729.1463
C6: TYPE 1 BOND Characteristics | D6: Values
C7: Coupon rate | D7: =+'Leverage finale'!AU10 -> 0.062301838
C8: Face value | D8: 1000
C12: TYPE 1 BOND (2025) | D12: 2025 | E12: 2026 | F12: 2027 | G12: 2028 | H12: 2029 | I12: 2030 | J12: 2031 | K12: 2032 | L12: 2033 | M12: 2034 | N12: 2035
C13: Cost of Debt | D13: =+D7 -> 0.062301838 | E13: =+'Leverage finale'!$AU$20 -> 0.066930524 | F13: =+'Leverage finale'!$AU$30 -> 0.06243134 | G13: =+'Leverage finale'!$AU$40 -> 0.063184948 | H13: =+'Leverage finale'!$AU$50 -> 0.055328756 | I13: =+'Leverage finale'!$AU$60 -> 0.063184948 | J13: =+'Leverage finale'!$AU$70 -> 0.055328756 | K13: =+'Leverage finale'!$AU$80 -> 0.055328756 | L13: =+'Leverage finale'!$AU$90 -> 0.055328756 | M13: =+'Leverage finale'!$AU$100 -> 0.055328756 | N13: =+'Leverage finale'!$AU$110 -> 0.055328756
C14: Annual coupon | D14: =$D$7*$D$8 -> 62.301838 | E14: =$D$7*$D$8 -> 62.301838 | F14: =$D$7*$D$8 -> 62.301838 | G14: =$D$7*$D$8 -> 62.301838 | H14: =$D$7*$D$8 -> 62.301838 | I14: =$D$7*$D$8 -> 62.301838 | J14: =$D$7*$D$8 -> 62.301838 | K14: =$D$7*$D$8 -> 62.301838 | ... N14: =$D$7*$D$8 -> 62.301838
C15: Bond Face Value | N15: =+D8 -> 1000
C16: Present Value of Cash Flows | D16: =D14/(1+D13) -> 58.647962 | E16: =E14/((1+E13)*(1+D13)) -> 54.968867 | F16: =F14/((1+F13)*(1+E13)*(1+D13)) -> 51.738748 | G16: =G14/((1+G13)*(1+F13)*(1+E13)*(1+D13)) -> 48.66392 | H16: =(H14)/((1+H13)*(1+G13)*(1+F13)*(1+E13)*(1+D13)) -> 46.112569 | I16: =(I14)/((1+D13)*(1+I13)*(1+H13)*(1+G13)*(1+F13)*(1+E13)) -> 43.372105 | J16: =(J14)/((1+J13)*(1+D13)*(1+I13)*(1+H13)*(1+G13)*(1+F13)*(1+E13)) -> 41.098193 | K16: =(K14)/((1+K13)*(1+J13)*(1+D13)*(1+I13)*(1+H13)*(1+G13)*(1+F13)*(1+E13)) -> 38.943498 | L16: =(L14)/((1+L13)*(1+K13)*(1+J13)*(1+D13)*(1+I13)*(1+H13)*(1+G13)*(1+F13)*(1+E13)) -> 36.901769 | M16: =(M14)/((1+M13)*(1+L13)*(1+K13)*(1+J13)*(1+D13)*(1+I13)*(1+H13)*(1+G13)*(1+F13)*(1+E13)) -> 34.967084 | N16: =(N14+N15)/((1+N13)*(1+M13)*(1+L13)*(1+K13)*(1+J13)*(1+D13)*(1+I13)*(1+H13)*(1+G13)*(1+F13)*(1+E13)) -> 564.96132
C17: Total PV of Type 1 Bond | D17: =SUM(D16:N16) -> 1020.376
C20: TYPE 2 BOND Characteristics | D20: Values
C21: Coupon rate | D21: =+'Leverage finale'!AU20 -> 0.066930524
C22: Face value | D22: 1000
C26: TYPE 2 BOND (2026) | D26: 2026 | E26: 2027 | F26: 2028 | G26: 2029 | H26: 2030 | I26: 2031 | J26: 2032 | K26: 2033 | L26: 2034 | M26: 2035 | N26: 2036
C27: Cost of Debt | D27: =+E13 -> 0.066930524 | E27: =+F13 -> 0.06243134 | F27: =+G13 -> 0.063184948 | G27: =+H13 -> 0.055328756 | H27: =+I13 -> 0.063184948 | I27: =+J13 -> 0.055328756 | J27: =+K13 -> 0.055328756 | K27: =+L13 -> 0.055328756 | ... M27: =+N13 -> 0.055328756 | N27: =+Tableau6[[#This Row],[2035]] -> 0.055328756
C28: Annual coupon | D28: =$D$22*$D$21 -> 66.930524 | E28: =$D$22*$D$21 -> 66.930524 | F28: =$D$22*$D$21 -> 66.930524 | G28: =$D$22*$D$21 -> 66.930524 | H28: =$D$22*$D$21 -> 66.930524 | I28: =$D$22*$D$21 -> 66.930524 | J28: =$D$22*$D$21 -> 66.930524 | K28: =$D$22*$D$21 -> 66.930524 | ... N28: =$D$22*$D$21 -> 66.930524
C29: Bond Face Value | N29: =+D22 -> 1000
C30: PV of each CF (all discounted to 2025) | D30: =D28/(1+D27) -> 62.731849 | E30: =E28/((1+E27)*(1+D27)) -> 59.045555 | F30: =F28/((1+F27)*(1+E27)*(1+D27)) -> 55.536485 | G30: =G28/((1+G27)*(1+F27)*(1+E27)*(1+D27)) -> 52.62482 | H30: =(H28)/((1+H27)*(1+G27)*(1+F27)*(1+E27)*(1+D27)) -> 49.497333 | I30: =(I28)/((1+D27)*(1+I27)*(1+H27)*(1+G27)*(1+F27)*(1+E27)) -> 46.902288 | J30: =(J28)/((1+J27)*(1+D27)*(1+I27)*(1+H27)*(1+G27)*(1+F27)*(1+E27)) -> 44.443296 | K30: =(K28)/((1+K27)*(1+J27)*(1+D27)*(1+I27)*(1+H27)*(1+G27)*(1+F27)*(1+E27)) -> 42.113223 | L30: =(L28)/((1+L27)*(1+K27)*(1+J27)*(1+D27)*(1+I27)*(1+H27)*(1+G27)*(1+F27)*(1+E27)) -> 39.905312 | M30: =(M28)/((1+M27)*(1+L27)*(1+K27)*(1+J27)*(1+D27)*(1+I27)*(1+H27)*(1+G27)*(1+F27)*(1+E27)) -> 37.813157 | N30: =(N28+N29)/((1+N27)*(1+M27)*(1+L27)*(1+K27)*(1+J27)*(1+D27)*(1+I27)*(1+H27)*(1+G27)*(1+F27)*(1+E27)) -> 571.17223
C31: PV Bond Type 2 | D31: =SUM(D30:N30) -> 1061.7855
C34: TYPE 3 BOND Characteristics | D34: Values
C35: Coupon rate | D35: =+'Leverage finale'!AU30 -> 0.06243134
C36: Face value | D36: 1000
C39: TYPE 3 BOND (2027) | D39: 2027 | E39: 2028 | F39: 2029 | G39: 2030 | H39: 2031 | I39: 2032 | J39: 2033 | K39: 2034 | L39: 2035 | M39: 2036 | N39: 2037
C40: Cost of Debt | D40: =+E27 -> 0.06243134 | E40: =+F27 -> 0.063184948 | F40: =+G27 -> 0.055328756 | G40: =+H27 -> 0.063184948 | H40: =+I27 -> 0.055328756 | I40: =+J27 -> 0.055328756 | J40: =+K27 -> 0.055328756 | K40: =+L27 -> 0.055328756 | L40: =+M27 -> 0.055328756 | M40: =+Tableau11[[#This Row],[2035]] -> 0.055328756 | N40: =+Tableau11[[#This Row],[2036]] -> 0.055328756
C41: Annual coupon | D41: =$D$35*$D$36 -> 62.43134 | E41: =$D$35*$D$36 -> 62.43134 | F41: =$D$35*$D$36 -> 62.43134 | G41: =$D$35*$D$36 -> 62.43134 | H41: =$D$35*$D$36 -> 62.43134 | I41: =$D$35*$D$36 -> 62.43134 | J41: =$D$35*$D$36 -> 62.43134 | K41: =$D$35*$D$36 -> 62.43134 | ... N41: =$D$35*$D$36 -> 62.43134
C42: Bond Face Value | N42: =+D36 -> 1000
C43: PV of each CF (all discounted to 2026) | D43: =D41/(1+D40) -> 58.762706 | E43: =E41/((1+E40)*(1+D40)) -> 55.270445 | F43: =F41/((1+F40)*(1+E40)*(1+D40)) -> 52.372727 | G43: =G41/((1+G40)*(1+F40)*(1+E40)*(1+D40)) -> 49.260223 | H43: =(H41)/((1+H40)*(1+G40)*(1+F40)*(1+E40)*(1+D40)) -> 46.677609 | I43: =(I41)/((1+D40)*(1+I40)*(1+H40)*(1+G40)*(1+F40)*(1+E40)) -> 44.230396 | J43: =(J41)/((1+J40)*(1+D40)*(1+I40)*(1+H40)*(1+G40)*(1+F40)*(1+E40)) -> 41.911486 | K43: =(K41)/((1+K40)*(1+J40)*(1+D40)*(1+I40)*(1+H40)*(1+G40)*(1+F40)*(1+E40)) -> 39.714151 | L43: =(L41)/((1+L40)*(1+K40)*(1+J40)*(1+D40)*(1+I40)*(1+H40)*(1+G40)*(1+F40)*(1+E40)) -> 37.632018 | M43: =(M41)/((1+M40)*(1+L40)*(1+K40)*(1+J40)*(1+D40)*(1+I40)*(1+H40)*(1+G40)*(1+F40)*(1+E40)) -> 35.659048 | N43: =(N41+N42)/((1+N40)*(1+M40)*(1+L40)*(1+K40)*(1+J40)*(1+D40)*(1+I40)*(1+H40)*(1+G40)*(1+F40)*(1+E40)) -> 575.01634
C44: PV Bond Type 3 | D44: =SUM(D43:N43) -> 1036.5071
C47: TYPE 4 BOND Characteristics | D47: Values
C48: Coupon rate | D48: =+'Leverage finale'!AU40 -> 0.063184948
C49: Face value | D49: 1000
C52: TYPE 4 BOND (2028) | D52: 2028 | E52: 2029 | F52: 2030 | G52: 2031 | H52: 2032 | I52: 2033 | J52: 2034 | K52: 2035 | L52: 2036 | M52: 2037 | N52: 2038
C53: Cost of Debt | D53: =+E40 -> 0.063184948 | E53: =+F40 -> 0.055328756 | F53: =+G40 -> 0.063184948 | G53: =+H40 -> 0.055328756 | H53: =+I40 -> 0.055328756 | I53: =+J40 -> 0.055328756 | J53: =+K40 -> 0.055328756 | K53: =+L40 -> 0.055328756 | L53: =+Tableau16[[#This Row],[2035]] -> 0.055328756 | M53: =+Tableau16[[#This Row],[2036]] -> 0.055328756 | N53: =+Tableau16[[#This Row],[2037]] -> 0.055328756
C54: Annual coupon | D54: =$D$48*$D$49 -> 63.184948 | E54: =$D$48*$D$49 -> 63.184948 | F54: =$D$48*$D$49 -> 63.184948 | G54: =$D$48*$D$49 -> 63.184948 | H54: =$D$48*$D$49 -> 63.184948 | I54: =$D$48*$D$49 -> 63.184948 | J54: =$D$48*$D$49 -> 63.184948 | K54: =$D$48*$D$49 -> 63.184948 | ... N54: =$D$48*$D$49 -> 63.184948
C55: Bond Face Value | N55: =+D49 -> 1000
C56: PV of each CF (all discounted to 2027) | D56: =D54/(1+D53) -> 59.429874 | E56: =E54/((1+E53)*(1+D53)) -> 56.314086 | F56: =F54/((1+F53)*(1+E53)*(1+D53)) -> 52.967347 | G56: =G54/((1+G53)*(1+F53)*(1+E53)*(1+D53)) -> 50.190376 | H56: =(H54)/((1+H53)*(1+G53)*(1+F53)*(1+E53)*(1+D53)) -> 47.558996 | I56: =(I54)/((1+D53)*(1+I53)*(1+H53)*(1+G53)*(1+F53)*(1+E53)) -> 45.065574 | J56: =(J54)/((1+J53)*(1+D53)*(1+I53)*(1+H53)*(1+G53)*(1+F53)*(1+E53)) -> 42.702877 | K56: =(K54)/((1+K53)*(1+J53)*(1+D53)*(1+I53)*(1+H53)*(1+G53)*(1+F53)*(1+E53)) -> 40.464051 | L56: =(L54)/((1+L53)*(1+K53)*(1+J53)*(1+D53)*(1+I53)*(1+H53)*(1+G53)*(1+F53)*(1+E53)) -> 38.342603 | M56: =(M54)/((1+M53)*(1+L53)*(1+K53)*(1+J53)*(1+D53)*(1+I53)*(1+H53)*(1+G53)*(1+F53)*(1+E53)) -> 36.332377 | N56: =(N54+N55)/((1+N53)*(1+M53)*(1+L53)*(1+K53)*(1+J53)*(1+D53)*(1+I53)*(1+H53)*(1+G53)*(1+F53)*(1+E53)) -> 579.29694
C57: PV Bond Type 4 | D57: =SUM(D56:N56) -> 1048.6651
C60: TYPE 5 BOND Characteristics | D60: Values
...

Sheet Unlevered Cost of Capital
C4: To evaluate Unlevered Cost of Capital we'll go through 3 steps: ru = rf + beta * risk premium
C11: ACTUAL LEVERAGE
C12: Financial item | D12: Numbers (Current) | E12: Source | G12: Comments
C13: Net Debt | D13: =8433-'Excess Cash'!I5 -> 4693.8 | G13: Total debt (10K) - Excess Cash
C14: Market Cap | D14: 247910 | E14: https://finance.yahoo.com/quote/CRM/key-statistics/
C15: D/(D+E) | D15: =D13/(D13+D14) -> 0.018581668
C22: rf + beta * risk premium
C23: Financial item | E23: Fonte | G23: Comments | I23: How to calculate risk premium (https://pages.stern.nyu.edu/~adamodar/New_Home_Page/datafile/histimpl.html):
C24: rf | D24: 0.0407 | E24: https://www.bloomberg.com/markets/rates-bonds | I24: Period | J24: ERP
C25: risk premium | D25: =J25 -> 0.042479688 | I25: 1960-2024 | J25: 0.042479688
C26: beta | D26: ='BETA Calculation chosen'!O18 -> 1.2211485 | F26: If we compare that with the Beta (Software (System & Application)) 1,24 found on https://pages.stern.nyu.edu/~adamodar/, the value from our analysis is reasonable
C27: Unlevered cost of capital | D27: =D24+D26*D25 -> 0.092574006

Sheet Excess Cash
A1: In Milions
B2: 2018 | C2: 2019 | D2: 2020 | E2: 2021 | F2: 2022 | G2: 2023 | H2: 2024 | I2: 2025
A3: Cash and cash equivalent | B3: =2543+1978 -> 4521 | C3: =2669+1673 -> 4342 | D3: =4145+3802 -> 7947 | E3: =6195+5771 -> 11966 | F3: =5464+5073 -> 10537 | G3: =7016+5492 -> 12508 | H3: =8472+5722 -> 14194 | I3: =8848+5184 -> 14032
A4: Total assets | B4: 21984 | C4: 30737 | D4: 55126 | E4: 66301 | F4: 95209 | G4: 98849 | H4: 99823 | I4: 102928
A5: Excess Cash | B5: =MAX(B3-0.1*B4,0) -> 2322.6 | C5: =MAX(C3-0.1*C4,0) -> 1268.3 | D5: =MAX(D3-0.1*D4,0) -> 2434.4 | E5: =MAX(E3-0.1*E4,0) -> 5335.9 | F5: =MAX(F3-0.1*F4,0) -> 1016.1 | G5: =MAX(G3-0.1*G4,0) -> 2623.1 | H5: =MAX(H3-0.1*H4,0) -> 4211.7 | I5: =MAX(I3-0.1*I4,0) -> 3739.2

Sheet Buyback
A2: In millions
A3: Market Cap (July 2025) | B3: ='Unlevered Cost of Capital'!D14 -> 247910 | D3: New Stock Price (S)= | E3: VL/N
A4: Number of stocks (N) | B4: 952
A5: Value per stocks | B5: =B3/B4 -> 260.40966 | E5: =B8/B4 -> 226.05202
D7: Number of stocks acquired (X)= | E7: (N*D)/VL
A8: Value of the Levered Firm (VL) | B8: ='Leverage finale'!C52 -> 215201.52
A9: Debt Issued (initial debt=0) (D) | B9: ='Leverage finale'!C55 -> 42983.406 | D9: million | E9: =B9/E5 -> 190.14829
D11: Gain/loss per stock | E11: =E5-B5 -> -34.357643
D12: % gain/loss per stock | E12: =E11/B5 -> -0.1319369

Sheet Montecarlo 
C2: Fiscal Year end January 31 2025
B3: Year | C3: 2018 | D3: 2019 | E3: 2020 | F3: 2021 | G3: 2022 | H3: 2023 | N3: 2024 | O3: 2025 | P3: 2026 | Q3: 2027 | R3: 2028 | S3: 2029 | T3: 2030 | AA3: Coverage ratio | AC3: Rating | AD3: Spread | AE3: Default probability | AH3: Year 2025 | AI3: Iteration 0 | AJ3: Iteration 1 | AK3: Iteration 2 | AL3: Iteration 3 | AM3: Iteration 4 | AN3: Iteration 5 | AO3: Iteration 6 | AP3: Iteration 7 | AQ3: Iteration 8 | AR3: Iteration 9 | AS3: Iteration 10
AA4: > | AB4: ≤ to | AH4: Trailing interest coverage ratio | AJ4: =MAX(MIN($N$14/AI8,100000),-100000) -> 2.7503076 | AK4: =MAX(MIN($N$14/AJ8,100000),-100000) -> 1.7037674 | AL4: =MAX(MIN($N$14/AK8,100000),-100000) -> 1.1115941 | AM4: =MAX(MIN($N$14/AL8,100000),-100000) -> 0.87314759 | AN4: =MAX(MIN($N$14/AM8,100000),-100000) -> 0.87314759 | AO4: =MAX(MIN($N$14/AN8,100000),-100000) -> 0.87314759 | AP4: =MAX(MIN($N$14/AO8,100000),-100000) -> 0.87314759 | AQ4: =MAX(MIN($N$14/AP8,100000),-100000) -> 0.87314759 | ... AS4: =MAX(MIN($N$14/AR8,100000),-100000) -> 0.87314759
C5: 0 | D5: =+(D6-C6)/C6 -> 0.2601518 | E5: =+(E6-D6)/D6 -> 0.28730613 | F5: =+(F6-E6)/E6 -> 0.24295239 | G5: =+(G6-F6)/F6 -> 0.24656503 | H5: =+(H6-G6)/G6 -> 0.18345161 | N5: =+(N6-H6)/H6 -> 0.1117951 | O5: =+(O6-N6)/N6 -> 0.087156095 | P5: =(P6-O6)/P6 -> 0.081283667 | Q5: =(Q6-P6)/Q6 -> 0.083336037 | R5: =(R6-Q6)/R6 -> 0.08872468 | S5: =(S6-R6)/S6 -> 0.089837138 | T5: =(T6-S6)/T6 -> 0.0843095 | AA5: -100000 | AB5: 0.199999 | AC5: D | AD5: 0.12 | AE5: 0.9 | AH5: Credit rating | AJ5: =VLOOKUP(AJ4,$AA$5:$AE$17,3) -> BBB | AK5: =VLOOKUP(AK4,$AA$5:$AE$17,3) -> B | AL5: =VLOOKUP(AL4,$AA$5:$AE$17,3) -> CCC | AM5: =VLOOKUP(AM4,$AA$5:$AE$17,3) -> CCC | AN5: =VLOOKUP(AN4,$AA$5:$AE$17,3) -> CCC | AO5: =VLOOKUP(AO4,$AA$5:$AE$17,3) -> CCC | AP5: =VLOOKUP(AP4,$AA$5:$AE$17,3) -> CCC | AQ5: =VLOOKUP(AQ4,$AA$5:$AE$17,3) -> CCC | ... AS5: =VLOOKUP(AS4,$AA$5:$AE$17,3) -> CCC
C6: 10540 | D6: 13282 | E6: 17098 | F6: 21252 | G6: 26492 | H6: 31352 | N6: 34857 | O6: 37895 | P6: 41247.77 | Q6: 44997.7 | R6: 49378.82 | S6: 54252.73 | T6: 59247.89 | AA6: 0.2 | AB6: 0.649999 | AC6: C | AD6: 0.105 | AE6: 0.3 | AH6: Credit spread | AJ6: =VLOOKUP(AJ4,$AA$4:$AE$17,4) -> 0.025 | AK6: =VLOOKUP(AK4,$AA$4:$AE$17,4) -> 0.06 | AL6: =VLOOKUP(AL4,$AA$4:$AE$17,4) -> 0.0875 | AM6: =VLOOKUP(AM4,$AA$4:$AE$17,4) -> 0.0875 | AN6: =VLOOKUP(AN4,$AA$4:$AE$17,4) -> 0.0875 | AO6: =VLOOKUP(AO4,$AA$4:$AE$17,4) -> 0.0875 | AP6: =VLOOKUP(AP4,$AA$4:$AE$17,4) -> 0.0875 | AQ6: =VLOOKUP(AQ4,$AA$4:$AE$17,4) -> 0.0875 | ... AS6: =VLOOKUP(AS4,$AA$4:$AE$17,4) -> 0.0875
C7: 2773 | D7: 3451 | E7: 4235 | F7: 5438 | G7: 7026 | H7: 8360 | N7: 8541 | O7: 8643 | P7: =P6-P9*P6 -> 8051.5647 | Q7: =Q6-Q9*Q6 -> 8671.0568 | R7: =R6-R9*R6 -> 9525.1744 | S7: =S6-S9*S6 -> 11083.833 | T7: =T6-T9*T6 -> 11523.715 | AA7: 0.65 | AB7: 0.799999 | AC7: CC | AD7: 0.095 | AE7: 0.2 | AH7: Yield on debt | AJ7: =AJ6+$AH$74 -> 0.0657 | AK7: =AK6+$AH$74 -> 0.1007 | AL7: =AL6+$AH$74 -> 0.1282 | AM7: =AM6+$AH$74 -> 0.1282 | AN7: =AN6+$AH$74 -> 0.1282 | AO7: =AO6+$AH$74 -> 0.1282 | AP7: =AP6+$AH$74 -> 0.1282 | AQ7: =AQ6+$AH$74 -> 0.1282 | ... AS7: =AS6+$AH$74 -> 0.1282
C8: =+C7/C6 -> 0.26309298 | D8: =+D7/D6 -> 0.25982533 | E8: =+E7/E6 -> 0.24768979 | F8: =+F7/F6 -> 0.2558818 | G8: =+G7/G6 -> 0.26521214 | H8: =+H7/H6 -> 0.26664966 | N8: =+N7/N6 -> 0.24502969 | O8: =+O7/O6 -> 0.22807758 | P8: =+P7/P6 -> 0.1952 | Q8: =+Q7/Q6 -> 0.1927 | R8: =+R7/R6 -> 0.1929 | S8: =+S7/S6 -> 0.2043 | T8: =+T7/T6 -> 0.1945 | AA8: 0.8 | AB8: 1.249999 | AC8: CCC | AD8: 0.0875 | AE8: 0.099 | AH8: Interest paid | AI8: =$AH$74*$C$54 -> 1821.978 | AJ8: =$C$54*AJ7 -> 2941.1291 | AK8: =$C$54*AK7 -> 4507.9406 | AL8: =$C$54*AL7 -> 5739.0068 | AM8: =$C$54*AM7 -> 5739.0068 | AN8: =$C$54*AN7 -> 5739.0068 | AO8: =$C$54*AO7 -> 5739.0068 | AP8: =$C$54*AP7 -> 5739.0068 | AQ8: =$C$54*AQ7 -> 5739.0068 | ... AS8: =$C$54*AS7 -> 5739.0068
C9: =+C10/C6 -> 0.73690702 | D9: =+D10/D6 -> 0.74017467 | E9: =+E10/E6 -> 0.75231021 | F9: =+F10/F6 -> 0.7441182 | G9: =+G10/G6 -> 0.73478786 | H9: =+H10/H6 -> 0.73335034 | N9: =+N10/N6 -> 0.75497031 | O9: 0.8054 | P9: 0.8048 | Q9: 0.8073 | R9: 0.8071 | S9: 0.7957 | T9: 0.8055 | AA9: 1.25 | AB9: 1.499999 | AC9: B- | AD9: 0.0675 | AE9: 0.07 | AH9: Prob of default | AJ9: =VLOOKUP(AJ4,$AA$5:$AE$17,5) -> 0.004 | AK9: =VLOOKUP(AK4,$AA$5:$AE$17,5) -> 0.052 | AL9: =VLOOKUP(AL4,$AA$5:$AE$17,5) -> 0.099 | AM9: =VLOOKUP(AM4,$AA$5:$AE$17,5) -> 0.099 | AN9: =VLOOKUP(AN4,$AA$5:$AE$17,5) -> 0.099 | AO9: =VLOOKUP(AO4,$AA$5:$AE$17,5) -> 0.099 | AP9: =VLOOKUP(AP4,$AA$5:$AE$17,5) -> 0.099 | AQ9: =VLOOKUP(AQ4,$AA$5:$AE$17,5) -> 0.099 | ... AS9: =VLOOKUP(AS4,$AA$5:$AE$17,5) -> 0.099
C10: =+C6-C7 -> 7767 | D10: =+D6-D7 -> 9831 | E10: =+E6-E7 -> 12863 | F10: =+F6-F7 -> 15814 | G10: =+G6-G7 -> 19466 | H10: =+H6-H7 -> 22992 | N10: =+N6-N7 -> 26316 | O10: =+O6-O7 -> 29252 | P10: =+P6-P7 -> 33196.205 | Q10: =+Q6-Q7 -> 36326.643 | R10: =+R6-R7 -> 39853.646 | S10: =+S6-S7 -> 43168.897 | T10: =+T6-T7 -> 47724.175 | AA10: 1.5 | AB10: 1.749999 | AC10: B | AD10: 0.06 | AE10: 0.052 | AH10: Cost of debt | AJ10: =(1-AJ9+AJ9*$AH$78)*(1+AJ7)-1 -> 0.063184948 | AK10: =(1-AK9+AK9*$AH$78)*(1+AK7)-1 -> 0.066930524 | AL10: =(1-AL9+AL9*$AH$78)*(1+AL7)-1 -> 0.062301838 | AM10: =(1-AM9+AM9*$AH$78)*(1+AM7)-1 -> 0.062301838 | AN10: =(1-AN9+AN9*$AH$78)*(1+AN7)-1 -> 0.062301838 | AO10: =(1-AO9+AO9*$AH$78)*(1+AO7)-1 -> 0.062301838 | AP10: =(1-AP9+AP9*$AH$78)*(1+AP7)-1 -> 0.062301838 | AQ10: =(1-AQ9+AQ9*$AH$78)*(1+AQ7)-1 -> 0.062301838 | ... AS10: =(1-AS9+AS9*$AH$78)*(1+AS7)-1 -> 0.062301838
C11: 7313 | D11: 9296 | E11: 12566 | F11: 15359 | G11: 18918 | H11: 21962 | N11: 21305 | O11: 22047 | P11: =+P6*P12 -> 26034.23 | Q11: =+Q6*Q12 -> 27361.156 | R11: =+R6*R12 -> 29973.199 | S11: =+S6*S12 -> 33387.653 | T11: =+T6*T12 -> 36150.526 | AA11: 1.75 | AB11: 1.999999 | AC11: B+ | AD11: 0.055 | AE11: 0.03
C12: =+C11/C6 -> 0.69383302 | D12: =+D11/D6 -> 0.69989459 | E12: =+E11/E6 -> 0.73493976 | F12: =+F11/F6 -> 0.72270845 | G12: =+G11/G6 -> 0.71410237 | H12: =+H11/H6 -> 0.70049758 | N12: =+N11/N6 -> 0.61121152 | O12: =+O11/O6 -> 0.58179179 | P12: =+AVERAGE(H12:O12) -> 0.63116696 | Q12: =+AVERAGE(N12:P12) -> 0.60805676 | R12: =+AVERAGE(O12:Q12) -> 0.60700517 | S12: =+AVERAGE(P12:R12) -> 0.61540963 | T12: =+AVERAGE(Q12:S12) -> 0.61015719 | AA12: 2.5 | AB12: 2.999999 | AC12: BBB | AD12: 0.025 | AE12: 0.004
O13: 12498 | P13: 14029.39 | Q13: 15720.75 | R13: 17726.86 | S13: 20720.8 | T13: 23559.75 | AA13: 3 | AB13: 4.249999 | AC13: A- | AD13: 0.0165 | AE13: 0.003 | AH13: Year 2026 | AI13: Iteration 0 | AJ13: Iteration 1 | AK13: Iteration 2 | AL13: Iteration 3 | AM13: Iteration 4 | AN13: Iteration 5 | AO13: Iteration 6 | AP13: Iteration 7 | AQ13: Iteration 8 | AR13: Iteration 9 | AS13: Iteration 10
C14: =+C10-C11 -> 454 | D14: =+D10-D11 -> 535 | E14: =+E10-E11 -> 297 | F14: =+F10-F11 -> 455 | G14: =+G10-G11 -> 548 | H14: =+H10-H11 -> 1030 | N14: =+N10-N11 -> 5011 | O14: =+O10-O11 -> 7205 | P14: =+P10-P11 -> 7161.9756 | Q14: =+Q10-Q11 -> 8965.4876 | R14: =+R10-R11 -> 9880.4465 | S14: =+S10-S11 -> 9781.2447 | T14: =+T10-T11 -> 11573.649 | AA14: 4.25 | AB14: 5.499999 | AC14: A | AD14: 0.014 | AE14: 0.002 | AH14: Trailing interest coverage ratio | AJ14: =MAX(MIN($O$14/AI18,100000),-100000) -> 3.5636789 | AK14: =MAX(MIN($O$14/AJ18,100000),-100000) -> 2.5356946 | AL14: =MAX(MIN($O$14/AK18,100000),-100000) -> 2.2076367 | AM14: =MAX(MIN($O$14/AL18,100000),-100000) -> 1.5155876 | AN14: =MAX(MIN($O$14/AM18,100000),-100000) -> 1.440335 | AO14: =MAX(MIN($O$14/AN18,100000),-100000) -> 1.3404966 | AP14: =MAX(MIN($O$14/AO18,100000),-100000) -> 1.3404966 | AQ14: =MAX(MIN($O$14/AP18,100000),-100000) -> 1.3404966 | ... AS14: =MAX(MIN($O$14/AR18,100000),-100000) -> 1.3404966
C15: =+C14/C6 -> 0.043074004 | D15: =+D14/D6 -> 0.040280078 | E15: =+E14/E6 -> 0.017370453 | F15: =+F14/F6 -> 0.02140975 | G15: =+G14/G6 -> 0.02068549 | H15: =+H14/H6 -> 0.032852769 | N15: =+N14/N6 -> 0.14375879 | O15: =+O13/O6 -> 0.32980604 | P15: =+P13/P6 -> 0.34012481 | Q15: =+Q13/Q6 -> 0.34936786 | R15: =+R13/R6 -> 0.35899724 | S15: =+S13/S6 -> 0.38193101 | T15: =+T13/T6 -> 0.39764707 | AA15: 5.5 | AB15: 6.499999 | AC15: A+ | AD15: 0.013 | AE15: 0.0015 | AH15: Credit rating | AJ15: =VLOOKUP(AJ14,$AA$5:$AE$17,3) -> A- | AK15: =VLOOKUP(AK14,$AA$5:$AE$17,3) -> BBB | AL15: =VLOOKUP(AL14,$AA$5:$AE$17,3) -> B+ | AM15: =VLOOKUP(AM14,$AA$5:$AE$17,3) -> B | AN15: =VLOOKUP(AN14,$AA$5:$AE$17,3) -> B- | AO15: =VLOOKUP(AO14,$AA$5:$AE$17,3) -> B- | AP15: =VLOOKUP(AP14,$AA$5:$AE$17,3) -> B- | AQ15: =VLOOKUP(AQ14,$AA$5:$AE$17,3) -> B- | ... AS15: =VLOOKUP(AS14,$AA$5:$AE$17,3) -> B-
O16: 12731 | P16: 14060.64 | Q16: 15762.05 | R16: 17811.23 | S16: 20224.55 | T16: 22452.55 | AA16: 6.5 | AB16: 8.499999 | AC16: AA | AD16: 0.0115 | AE16: 0.0005 | AH16: Credit spread | AJ16: =VLOOKUP(AJ14,$AA$5:$AE$17,4) -> 0.0165 | AK16: =VLOOKUP(AK14,$AA$4:$AE$17,4) -> 0.025 | AL16: =VLOOKUP(AL14,$AA$4:$AE$17,4) -> 0.055 | AM16: =VLOOKUP(AM14,$AA$4:$AE$17,4) -> 0.06 | AN16: =VLOOKUP(AN14,$AA$4:$AE$17,4) -> 0.0675 | AO16: =VLOOKUP(AO14,$AA$4:$AE$17,4) -> 0.0675 | AP16: =VLOOKUP(AP14,$AA$4:$AE$17,4) -> 0.0675 | AQ16: =VLOOKUP(AQ14,$AA$4:$AE$17,4) -> 0.0675 | AR16: =VLOOKUP(AR14,$AA$4:$AE$17,4) -> 0.0675 | AS16: =VLOOKUP(AS14,$AA$4:$AE$17,4) -> 0.0675
C17: 420 | D17: 983 | E17: 706 | F17: 2561 | G17: 1532 | H17: 660 | N17: 4950 | O17: 7438 | P17: 8887.15 | Q17: 10449.59 | R17: 12731.48 | S17: 13635.45 | T17: 15430.1 | AA17: 8.5 | AB17: 100000 | AC17: AAA | AD17: 0.0065 | AE17: 0.0001 | AH17: Yield on debt | AJ17: =AJ16+$AH$74 -> 0.0572 | AK17: =AK16+$AH$74 -> 0.0657 | AL17: =AL16+$AH$74 -> 0.0957 | AM17: =AM16+$AH$74 -> 0.1007 | AN17: =AN16+$AH$74 -> 0.1082 | AO17: =AO16+$AH$74 -> 0.1082 | AP17: =AP16+$AH$74 -> 0.1082 | AQ17: =AQ16+$AH$74 -> 0.1082 | ... AS17: =AS16+$AH$74 -> 0.1082
C18: =+C17/C6 -> 0.039848197 | D18: =+D17/D6 -> 0.074009938 | E18: =+E17/E6 -> 0.041291379 | F18: =+F17/F6 -> 0.12050631 | G18: =+G17/G6 -> 0.057828778 | H18: =+H17/H6 -> 0.021051289 | N18: =+N17/N6 -> 0.14200878 | O18: =+O17/O6 -> 0.19627919 | P18: =+P17/P6 -> 0.21545771 | Q18: =+Q17/Q6 -> 0.23222498 | R18: =+R17/R6 -> 0.25783281 | S18: =+S17/S6 -> 0.25133205 | T18: =+T17/T6 -> 0.2604329 | AH18: Interest paid | AI18: =+$D$54*$AH$74 -> 2021.7871 | AJ18: =$D$54*AJ17 -> 2841.4305 | AK18: =$D$54*AK17 -> 3263.6711 | AL18: =$D$54*AL17 -> 4753.9318 | AM18: =$D$54*AM17 -> 5002.3086 | AN18: =$D$54*AN17 -> 5374.8738 | AO18: =$D$54*AO17 -> 5374.8738 | AP18: =$D$54*AP17 -> 5374.8738 | AQ18: =$D$54*AQ17 -> 5374.8738 | ... AS18: =$D$54*AS17 -> 5374.8738
C19: -60 | D19: 127 | E19: -580 | F19: 1511 | G19: -88 | H19: -452 | N19: -814 | O19: -1241 | P19: =+P20-P17 -> -2018.65 | Q19: =+Q20-Q17 -> -2296.99 | R19: =+R20-R17 -> -3049.17 | S19: =+S20-S17 -> -2656.78 | T19: =+T20-T17 -> -2980.77 | AH19: Prob of default | AJ19: =VLOOKUP(AJ14,$AA$5:$AE$17,5) -> 0.003 | AK19: =VLOOKUP(AK14,$AA$5:$AE$17,5) -> 0.004 | AL19: =VLOOKUP(AL14,$AA$5:$AE$17,5) -> 0.03 | AM19: =VLOOKUP(AM14,$AA$5:$AE$17,5) -> 0.052 | AN19: =VLOOKUP(AN14,$AA$5:$AE$17,5) -> 0.07 | AO19: =VLOOKUP(AO14,$AA$5:$AE$17,5) -> 0.07 | AP19: =VLOOKUP(AP14,$AA$5:$AE$17,5) -> 0.07 | AQ19: =VLOOKUP(AQ14,$AA$5:$AE$17,5) -> 0.07 | ... AS19: =VLOOKUP(AS14,$AA$5:$AE$17,5) -> 0.07
C20: =+C17+C19 -> 360 | D20: =+D17+D19 -> 1110 | E20: =+E17+E19 -> 126 | F20: =+F17+F19 -> 4072 | G20: =+G17+G19 -> 1444 | H20: =+H17+H19 -> 208 | N20: =+N17+N19 -> 4136 | O20: =+O17+O19 -> 6197 | P20: 6868.5 | Q20: 8152.6 | R20: 9682.31 | S20: 10978.67 | T20: 12449.33 | AH20: Cost of debt | AJ20: =(1-AJ19+AJ19*$AH$78)*(1+AJ17)-1 -> 0.055328756 | AK20: =(1-AK19+AK19*$AH$78)*(1+AK17)-1 -> 0.063184948 | AL20: =(1-AL19+AL19*$AH$78)*(1+AL17)-1 -> 0.07630611 | AM20: =(1-AM19+AM19*$AH$78)*(1+AM17)-1 -> 0.066930524 | AN20: =(1-AN19+AN19*$AH$78)*(1+AN17)-1 -> 0.06243134 | AO20: =(1-AO19+AO19*$AH$78)*(1+AO17)-1 -> 0.06243134 | AP20: =(1-AP19+AP19*$AH$78)*(1+AP17)-1 -> 0.06243134 | AQ20: =(1-AQ19+AQ19*$AH$78)*(1+AQ17)-1 -> 0.06243134 | ... AS20: =(1-AS19+AS19*$AH$78)*(1+AS17)-1 -> 0.06243134
P21: =+O22*(1+P5) -> 14156.166 | Q21: =+P21*(1+Q5) -> 15335.885 | R21: =+Q21*(1+R5) -> 16696.556 | S21: =+R21*(1+S5) -> 18196.527 | T21: =+S21*(1+T5) -> 19730.667
C22: 2738 | D22: 3398 | E22: 4331 | F22: 4801 | G22: 6000 | H22: 7111 | N22: 10234 | O22: 13092 | P22: 14563.34 | Q22: 15855.26 | R22: 17566.88 | S22: 18236.25 | T22: 20608.25
C23: 417 | D23: 431 | E23: 342 | F23: 238 | G23: 802 | H23: 1188 | N23: 437 | O23: 77 | P23: =+AVERAGE(H23:O23)*(1+P5) -> 613.44827 | Q23: =+P23*(1+Q5) -> 664.57061 | R23: =+Q23*(1+R5) -> 723.53443 | S23: =+R23*(1+S5) -> 788.53469 | T23: =+S23*(1+T5) -> 855.01566 | AH23: Year 2027 | AI23: Iteration 0 | AJ23: Iteration 1 | AK23: Iteration 2 | AL23: Iteration 3 | AM23: Iteration 4 | AN23: Iteration 5 | AO23: Iteration 6 | AP23: Iteration 7 | AQ23: Iteration 8 | AR23: Iteration 9 | AS23: Iteration 10
D24: =+(D23-C23)/C23 -> 0.033573141 | E24: =+(E23-D23)/D23 -> -0.20649652 | F24: =+(F23-E23)/E23 -> -0.30409357 | G24: =+(G23-F23)/F23 -> 2.3697479 | H24: =+(H23-G23)/G23 -> 0.48129676 | N24: =+(N23-H23)/H23 -> -0.63215488 | O24: =+(O23-N23)/N23 -> -0.82379863 | P24: =+(P23-O23)/O23 -> 6.9668606 | Q24: =+(Q23-P23)/P23 -> 0.083336037 | R24: =+(R23-Q23)/Q23 -> 0.08872468 | S24: =+(S23-R23)/R23 -> 0.089837138 | T24: =+(T23-S23)/S23 -> 0.0843095 | AH24: Trailing interest coverage ratio | AJ24: =MAX(MIN($P$14/AI28,100000),-100000) -> 3.2041706 | AK24: =MAX(MIN($P$14/AJ28,100000),-100000) -> 2.2798907 | AL24: =MAX(MIN($P$14/AK28,100000),-100000) -> 1.3626933 | AM24: =MAX(MIN($P$14/AL28,100000),-100000) -> 1.2052657 | AN24: =MAX(MIN($P$14/AM28,100000),-100000) -> 1.0172367 | AO24: =MAX(MIN($P$14/AN28,100000),-100000) -> 1.0172367 | AP24: =MAX(MIN($P$14/AO28,100000),-100000) -> 1.0172367 | AQ24: =MAX(MIN($P$14/AP28,100000),-100000) -> 1.0172367 | ... AS24: =MAX(MIN($P$14/AR28,100000),-100000) -> 1.0172367
C25: =+C22-C23 -> 2321 | D25: =+D22-D23 -> 2967 | E25: =+E22-E23 -> 3989 | F25: =+F22-F23 -> 4563 | G25: =+G22-G23 -> 5198 | H25: =+H22-H23 -> 5923 | N25: =+N22-N23 -> 9797 | O25: =+O22-O23 -> 13015 | P25: =+P22-P23 -> 13949.892 | Q25: =+Q22-Q23 -> 15190.689 | R25: =+R22-R23 -> 16843.346 | S25: =+S22-S23 -> 17447.715 | T25: =+T22-T23 -> 19753.234 | AH25: Credit rating | AJ25: =VLOOKUP(AJ24,$AA$5:$AE$17,3) -> A- | AK25: =VLOOKUP(AK24,$AA$5:$AE$17,3) -> B+ | AL25: =VLOOKUP(AL24,$AA$5:$AE$17,3) -> B- | AM25: =VLOOKUP(AM24,$AA$5:$AE$17,3) -> CCC | AN25: =VLOOKUP(AN24,$AA$5:$AE$17,3) -> CCC | AO25: =VLOOKUP(AO24,$AA$5:$AE$17,3) -> CCC | AP25: =VLOOKUP(AP24,$AA$5:$AE$17,3) -> CCC | AQ25: =VLOOKUP(AQ24,$AA$5:$AE$17,3) -> CCC | ... AS25: =VLOOKUP(AS24,$AA$5:$AE$17,3) -> CCC
T26: =+T25*(1+AH79)/(AH73-AH79) -> 350548 | AH26: Credit spread | AJ26: =VLOOKUP(AJ24,$AA$5:$AE$17,4) -> 0.0165 | AK26: =VLOOKUP(AK24,$AA$5:$AE$17,4) -> 0.055 | AL26: =VLOOKUP(AL24,$AA$5:$AE$17,4) -> 0.0675 | AM26: =VLOOKUP(AM24,$AA$5:$AE$17,4) -> 0.0875 | AN26: =VLOOKUP(AN24,$AA$5:$AE$17,4) -> 0.0875 | AO26: =VLOOKUP(AO24,$AA$5:$AE$17,4) -> 0.0875 | AP26: =VLOOKUP(AP24,$AA$5:$AE$17,4) -> 0.0875 | AQ26: =VLOOKUP(AQ24,$AA$5:$AE$17,4) -> 0.0875 | ... AS26: =VLOOKUP(AS24,$AA$5:$AE$17,4) -> 0.0875
C27: =+C25 -> 2321 | D27: =+D25 -> 2967 | E27: =+E25 -> 3989 | F27: =+F25 -> 4563 | G27: =+G25 -> 5198 | H27: =+H25 -> 5923 | N27: =+N25 -> 9797 | O27: =+O25 -> 13015 | P27: =+P25 -> 13949.892 | Q27: =+Q25 -> 15190.689 | R27: =+R25 -> 16843.346 | S27: =+S25 -> 17447.715 | T27: =+T25+T26 -> 370301.23 | AH27: Yield on debt | AJ27: =AJ26+$AH$74 -> 0.0572 | AK27: =AK26+$AH$74 -> 0.0957 | AL27: =AL26+$AH$74 -> 0.1082 | AM27: =AM26+$AH$74 -> 0.1282 | AN27: =AN26+$AH$74 -> 0.1282 | AO27: =AO26+$AH$74 -> 0.1282 | AP27: =AP26+$AH$74 -> 0.1282 | AQ27: =AQ26+$AH$74 -> 0.1282 | ... AS27: =AS26+$AH$74 -> 0.1282
O28: =+NPV($AH$73,O27:T27) -> 275968.44 | P28: =+NPV($AH$73,P27:T27) -> 288500.95 | Q28: =+NPV($AH$73,Q27:T27) -> 301258.75 | R28: =+NPV($AH$73,R27:T27) -> 313956.79 | S28: =+NPV($AH$73,S27:T27) -> 326177.68 | T28: =+NPV($AH$73,T27) -> 338925.54 | AH28: Interest paid | AI28: =$AH$74*$E$54 -> 2235.2042 | AJ28: =$E$54*AJ27 -> 3141.368 | AK28: =$E$54*AK27 -> 5255.7503 | AL28: =$E$54*AL27 -> 5942.2381 | AM28: =$E$54*AM27 -> 7040.6185 | AN28: =$E$54*AN27 -> 7040.6185 | AO28: =$E$54*AO27 -> 7040.6185 | AP28: =$E$54*AP27 -> 7040.6185 | AQ28: =$E$54*AQ27 -> 7040.6185 | ... AS28: =$E$54*AS27 -> 7040.6185
AH29: Prob of default | AJ29: =VLOOKUP(AJ24,$AA$5:$AE$17,5) -> 0.003 | AK29: =VLOOKUP(AK24,$AA$5:$AE$17,5) -> 0.03 | AL29: =VLOOKUP(AL24,$AA$5:$AE$17,5) -> 0.07 | AM29: =VLOOKUP(AM24,$AA$5:$AE$17,5) -> 0.099 | AN29: =VLOOKUP(AN24,$AA$5:$AE$17,5) -> 0.099 | AO29: =VLOOKUP(AO24,$AA$5:$AE$17,5) -> 0.099 | AP29: =VLOOKUP(AP24,$AA$5:$AE$17,5) -> 0.099 | AQ29: =VLOOKUP(AQ24,$AA$5:$AE$17,5) -> 0.099 | ... AS29: =VLOOKUP(AS24,$AA$5:$AE$17,5) -> 0.099
G30: EXCESS CASH | H30: ='Excess Cash'!I5 -> 3739.2 | N30: Total Value | O30: =H30+O28 -> 279707.64 | AH30: Cost of debt | AJ30: =(1-AJ29+AJ29*$AH$78)*(1+AJ27)-1 -> 0.055328756 | AK30: =(1-AK29+AK29*$AH$78)*(1+AK27)-1 -> 0.07630611 | AL30: =(1-AL29+AL29*$AH$78)*(1+AL27)-1 -> 0.06243134 | AM30: =(1-AM29+AM29*$AH$78)*(1+AM27)-1 -> 0.062301838 | AN30: =(1-AN29+AN29*$AH$78)*(1+AN27)-1 -> 0.062301838 | AO30: =(1-AO29+AO29*$AH$78)*(1+AO27)-1 -> 0.062301838 | AP30: =(1-AP29+AP29*$AH$78)*(1+AP27)-1 -> 0.062301838 | AQ30: =(1-AQ29+AQ29*$AH$78)*(1+AQ27)-1 -> 0.062301838 | ... AS30: =(1-AS29+AS29*$AH$78)*(1+AS27)-1 -> 0.062301838
O32: =+AS8 -> 5739.0068 | P32: =+AS18 -> 5374.8738 | Q32: =+AS28 -> 7040.6185 | R32: =+AS38 -> 6653.3634 | S32: =+AS48 -> 7385.0756 | T32: =+AS58 -> 9763.2056
O33: =$AH$72*$O$32 -> 946.05143 | P33: =$AH$72*$O$32 -> 946.05143 | Q33: =$AH$72*$O$32 -> 946.05143 | R33: =$AH$72*$O$32 -> 946.05143 | S33: =$AH$72*$O$32 -> 946.05143 | T33: =$AH$72*$O$32 -> 946.05143 | AH33: Year 2028 | AI33: Iteration 0 | AJ33: Iteration 1 | AK33: Iteration 2 | AL33: Iteration 3 | AM33: Iteration 4 | AN33: Iteration 5 | AO33: Iteration 6 | AP33: Iteration 7 | AQ33: Iteration 8 | AR33: Iteration 9 | AS33: Iteration 10
T34: =AH72*H54 -> 12554.008 | AH34: Trailing interest coverage ratio | AJ34: =MAX(MIN($Q$14/AI38,100000),-100000) -> 3.5823294 | AK34: =MAX(MIN($Q$14/AJ38,100000),-100000) -> 2.5489652 | AL34: =MAX(MIN($Q$14/AK38,100000),-100000) -> 2.2191904 | AM34: =MAX(MIN($Q$14/AL38,100000),-100000) -> 1.5235194 | AN34: =MAX(MIN($Q$14/AM38,100000),-100000) -> 1.447873 | AO34: =MAX(MIN($Q$14/AN38,100000),-100000) -> 1.3475121 | AP34: =MAX(MIN($Q$14/AO38,100000),-100000) -> 1.3475121 | AQ34: =MAX(MIN($Q$14/AP38,100000),-100000) -> 1.3475121 | ... AS34: =MAX(MIN($Q$14/AR38,100000),-100000) -> 1.3475121
O35: =O33+O34 -> 946.05143 | P35: =P33+P34 -> 946.05143 | Q35: =Q33+Q34 -> 946.05143 | R35: =R33+R34 -> 946.05143 | S35: =S33+S34 -> 946.05143 | T35: =T33+T34 -> 13500.06 | AH35: Credit rating | AJ35: =VLOOKUP(AJ34,$AA$5:$AE$17,3) -> A- | AK35: =VLOOKUP(AK34,$AA$5:$AE$17,3) -> BBB | AL35: =VLOOKUP(AL34,$AA$5:$AE$17,3) -> B+ | AM35: =VLOOKUP(AM34,$AA$5:$AE$17,3) -> B | AN35: =VLOOKUP(AN34,$AA$5:$AE$17,3) -> B- | AO35: =VLOOKUP(AO34,$AA$5:$AE$17,3) -> B- | AP35: =VLOOKUP(AP34,$AA$5:$AE$17,3) -> B- | AQ35: =VLOOKUP(AQ34,$AA$5:$AE$17,3) -> B- | ... AS35: =VLOOKUP(AS34,$AA$5:$AE$17,3) -> B-
